Workbook

Sheet Profit and Loss
A2: Profit- and Loss Projection for regular operation per anum
A3: Total Sales | C3: =SUM(C4:C5) -> 232900 | D3: =C3/$C$3 -> 1
B4: Revenue from Fares | C4: ='DASHVOLT REVENUE SCHEDULE'!H99 -> 232900 | D4: =C4/$C$3 -> 1
C5: 0 | D5: =C5/$C$3 -> 0
A6: Cost of goods sold (COGS) | C6: =SUM(C7:C8) -> 275700 | D6: =C6/$C$3 -> 1.1837699
B7: Fuel for Combustion Bikes | C7: 101300 | D7: =C7/$C$3 -> 0.43495062
B8: Riders' Share | C8: =SUM('RIDER REVENUE SCHEDULE'!F47:J97)+45000 -> 174400 | D8: =C8/$C$3 -> 0.74881924
B10: Gross Profit | C10: =C3-C6 -> -42800 | D10: =C10/$C$3 -> -0.18376986
B12: OPEX Costs | C12: =SUM(C13:C18) -> 0 | D12: =C12/$C$3 -> 0
B13: Salaries & Wages | C13: 0 | D13: =C13/$C$3 -> 0
B14: Repairs and Maintenance | C14: 0 | D14: =C14/$C$3 -> 0
B15: Utilities | C15: 0 | D15: =C15/$C$3 -> 0
B16: Marketing and Promotions | C16: 0 | D16: =C16/$C$3 -> 0
B17: Stationery and office supplies | C17: 0 | D17: =C17/$C$3 -> 0
B18: Miscelaneous | C18: =ROUNDUP(SUM(C13:C17)*0.05,-6) -> 0 | D18: =C18/$C$3 -> 0
B20: EBITA | C20: =C10-C12 -> -42800 | D20: =C20/$C$3 -> -0.18376986
A22: Taxes | C22: 0 | D22: =C22/$C$3 -> 0
B24: Earnings After Taxes | C24: =C20-C22 -> -42800 | D24: =C24/$C$3 -> -0.18376986

Sheet DASHVOLT REVENUE SCHEDULE
B3: DASHVOLT REVENUE SCHEDULE
B5: Date | C5: Bike Code | D5: Rider | E5: Status | F5: Location | G5: Revenue | H5: Balance
G6: 0 | H6: 0
B7: 45900 | D7: Bello Saulawa | E7: COMPLETED | F7: JAHI | G7: 2900 | H7: =H6+Table1[[#This Row],[Revenue]] -> 2900
B8: 45900 | D8: Bello Saulawa | E8: =E7 -> COMPLETED | F8: Mitama | G8: 2500 | H8: =H7+Table1[[#This Row],[Revenue]] -> 5400 | K8: Aminu Ibrahim
B9: 45900 | D9: Bello Saulawa | E9: cOMPLETED | F9: Mitama | G9: 2500 | H9: =H8+Table1[[#This Row],[Revenue]] -> 7900 | K9: Bello Saulawa | L9: P
B10: 45900 | D10: Bello Saulawa | E10: COMPLETED | F10: Dawaki | G10: 2900 | H10: =H9+Table1[[#This Row],[Revenue]] -> 10800 | K10: Murtala Hassan
B11: 45900 | D11: Bello Saulawa | E11: COMPLETED | F11: Jabi | G11: 2500 | H11: =H10+Table1[[#This Row],[Revenue]] -> 13300 | K11: Babangida Monde
B12: 45900 | D12: Bello Saulawa | E12: COMPLETED | F12: Dawaki | G12: 2900 | H12: =H11+Table1[[#This Row],[Revenue]] -> 16200 | K12: Bello Abdullahi
B13: 45900 | D13: Murtala Hassan | E13: COMPLETED | F13: Wuse2 | G13: 2500 | H13: =H12+Table1[[#This Row],[Revenue]] -> 18700
B14: 45900 | D14: Murtala Hassan | E14: COMPLETED | F14: Utako | G14: 2500 | H14: =H13+Table1[[#This Row],[Revenue]] -> 21200
B15: 45900 | D15: Murtala Hassan | E15: COMPLETED | F15: Life camp | G15: 2200 | H15: =H14+Table1[[#This Row],[Revenue]] -> 23400
B16: 45900 | D16: Murtala Hassan | E16: COMPLETED | F16: Kado | G16: 1700 | H16: =H15+Table1[[#This Row],[Revenue]] -> 25100
B17: 45900 | D17: Bello Abdullahi | E17: COMPLETED | F17: Wuse2 | G17: 2500 | H17: =H16+Table1[[#This Row],[Revenue]] -> 27600
B18: 45900 | D18: Bello Abdullahi | E18: COMPLETED | F18: Kado | G18: 1700 | H18: =H17+Table1[[#This Row],[Revenue]] -> 29300
B19: 45900 | D19: Bello Abdullahi | E19: COMPLETED | F19: Mitama | G19: 2500 | H19: =H18+Table1[[#This Row],[Revenue]] -> 31800
B20: 45900 | D20: Bello Abdullahi | E20: COMPLETED | F20: Wuse2 | G20: 2500 | H20: =H19+Table1[[#This Row],[Revenue]] -> 34300
B21: 45901 | D21: Bello Saulawa | E21: COMPLETED | F21: Guzape | G21: 3200 | H21: =H20+Table1[[#This Row],[Revenue]] -> 37500
B22: 45901 | D22: Bello Saulawa | E22: COMPLETED | F22: Jabi | G22: 2500 | H22: =H21+Table1[[#This Row],[Revenue]] -> 40000
B23: 45901 | D23: Bello Saulawa | E23: COMPLETED | F23: CBD | G23: 2700 | H23: =H22+Table1[[#This Row],[Revenue]] -> 42700
B24: 45901 | D24: Bello Saulawa | E24: COMPLETED | F24: Garki | G24: 3000 | H24: =H23+Table1[[#This Row],[Revenue]] -> 45700
... B59: 45904 | D59: Bello Abdullahi | E59: cOMPLETED | F59: Gishiri | G59: 2500 | H59: =H58+Table1[[#This Row],[Revenue]] -> 135500
B60: =B59 -> 45904 | D60: Murtala Hassan | E60: COMPLETED | F60: Wuse6 | G60: 2500 | H60: =H59+Table1[[#This Row],[Revenue]] -> 138000
B61: =B60 -> 45904 | D61: Murtala Hassan | E61: COMPLETED | F61: wuse zone 6 | G61: 2500 | H61: =H60+Table1[[#This Row],[Revenue]] -> 140500
B62: =B61 -> 45904 | D62: Murtala Hassan | E62: COMPLETED | F62: Wuse2 | G62: 2500 | H62: =H61+Table1[[#This Row],[Revenue]] -> 143000
B63: =B62 -> 45904 | D63: Murtala Hassan | E63: COMPLETED | F63: Jahi | G63: 2200 | H63: =H62+Table1[[#This Row],[Revenue]] -> 145200
B64: =B63 -> 45904 | D64: Bello Saulawa | E64: COMPLETED | F64: Life camp | G64: 2200 | H64: =H63+Table1[[#This Row],[Revenue]] -> 147400
B65: =B64 -> 45904 | D65: Bello Saulawa | E65: COMPLETED | F65: Garki2 | G65: 3000 | H65: =H64+Table1[[#This Row],[Revenue]] -> 150400
B66: =B65 -> 45904 | D66: Bello Saulawa | E66: COMPLETED | F66: Garki2 | G66: 3000 | H66: =H65+Table1[[#This Row],[Revenue]] -> 153400
B67: =B66 -> 45904 | D67: Murtala Hassan | E67: COMPLETED | F67: mabushi | G67: 2200 | H67: =H66+Table1[[#This Row],[Revenue]] -> 155600
B68: =B67 -> 45904 | D68: Murtala Hassan | E68: COMPLETED | F68: Maitama | G68: 2500 | H68: =H67+Table1[[#This Row],[Revenue]] -> 158100
B69: =B68 -> 45904 | D69: Murtala Hassan | E69: COMPLETED | F69: Gwarimpa | G69: 2700 | H69: =H68+Table1[[#This Row],[Revenue]] -> 160800
B70: =B69 -> 45904 | D70: Bello Abdullahi | E70: COMPLETED | F70: CBD | G70: 2700 | H70: =H69+Table1[[#This Row],[Revenue]] -> 163500
B71: =B70 -> 45904 | D71: Bello Abdullahi | E71: COMPLETED | F71: wuse zone 5 | G71: 2500 | H71: =H70+Table1[[#This Row],[Revenue]] -> 166000
... B76: =B75 -> 45904 | D76: Bello Abdullahi | E76: COMPLETED | F76: Kado | G76: 1700 | H76: =H75+Table1[[#This Row],[Revenue]] -> 178000
B77: 45905 | D77: Murtala Hassan | E77: COMPLETED | F77: Gwarimpa | G77: 2700 | H77: =H76+Table1[[#This Row],[Revenue]] -> 180700
B78: 45905 | D78: Murtala Hassan | E78: COMPLETED | F78: Gwarimpa | G78: 2700 | H78: =H77+Table1[[#This Row],[Revenue]] -> 183400
B79: 45905 | D79: Murtala Hassan | E79: COMPLETED | F79: Katempe Extention | G79: 2700 | H79: =H78+Table1[[#This Row],[Revenue]] -> 186100
B80: 45905 | D80: Bello Abdullahi | E80: COMPLETED | F80: Apo | G80: 3200 | H80: =H79+Table1[[#This Row],[Revenue]] -> 189300
B81: 45905 | D81: Bello Saulawa | E81: COMPLETED | F81: Kado | G81: 1700 | H81: =H80+Table1[[#This Row],[Revenue]] -> 191000
...

Sheet RIDER REVENUE SCHEDULE
B3: DASHVOLT REVENUE SCHEDULE PER RIDER
B5: Date | C5: Bike Code | D5: Status | E5: Location | F5: Aminu Ibrahim | G5: Bello Saulawa | H5: Murtala Hassan | I5: Babangida Monde | J5: Bello Abdullahi
B6: ='DASHVOLT REVENUE SCHEDULE'!B7 -> 45900 | C6: ='DASHVOLT REVENUE SCHEDULE'!C7 -> 0 | D6: ='DASHVOLT REVENUE SCHEDULE'!E7 -> COMPLETED | E6: ='DASHVOLT REVENUE SCHEDULE'!F7 -> JAHI | F6: =IF('DASHVOLT REVENUE SCHEDULE'!D7= "Aminu Ibrahim", 'DASHVOLT REVENUE SCHEDULE'!G7, 0) -> 0 | G6: =IF('DASHVOLT REVENUE SCHEDULE'!D7= "Bello Saulawa",'DASHVOLT REVENUE SCHEDULE'!G7, 0) -> 2900 | H6: =IF('DASHVOLT REVENUE SCHEDULE'!D7= "Murtala Hassan", 'DASHVOLT REVENUE SCHEDULE'!G7, 0) -> 0 | I6: =IF('DASHVOLT REVENUE SCHEDULE'!D7= "Babangida Monde", 'DASHVOLT REVENUE SCHEDULE'!G7, 0) -> 0 | J6: =IF('DASHVOLT REVENUE SCHEDULE'!D7= "Bello Abdullahi", 'DASHVOLT REVENUE SCHEDULE'!G7, 0) -> 0
B7: ='DASHVOLT REVENUE SCHEDULE'!B8 -> 45900 | C7: ='DASHVOLT REVENUE SCHEDULE'!C8 -> 0 | D7: ='DASHVOLT REVENUE SCHEDULE'!E8 -> COMPLETED | E7: ='DASHVOLT REVENUE SCHEDULE'!F8 -> Mitama | F7: =IF('DASHVOLT REVENUE SCHEDULE'!D8= "Aminu Ibrahim", 'DASHVOLT REVENUE SCHEDULE'!G8, 0) -> 0 | G7: =IF('DASHVOLT REVENUE SCHEDULE'!D8= "Bello Saulawa",'DASHVOLT REVENUE SCHEDULE'!G8, 0) -> 2500 | H7: =IF('DASHVOLT REVENUE SCHEDULE'!D8= "Murtala Hassan", 'DASHVOLT REVENUE SCHEDULE'!G8, 0) -> 0 | I7: =IF('DASHVOLT REVENUE SCHEDULE'!D8= "Babangida Monde", 'DASHVOLT REVENUE SCHEDULE'!G8, 0) -> 0 | J7: =IF('DASHVOLT REVENUE SCHEDULE'!D8= "Bello Abdullahi", 'DASHVOLT REVENUE SCHEDULE'!G8, 0) -> 0
B8: ='DASHVOLT REVENUE SCHEDULE'!B9 -> 45900 | C8: ='DASHVOLT REVENUE SCHEDULE'!C9 -> 0 | D8: ='DASHVOLT REVENUE SCHEDULE'!E9 -> cOMPLETED | E8: ='DASHVOLT REVENUE SCHEDULE'!F9 -> Mitama | F8: =IF('DASHVOLT REVENUE SCHEDULE'!D9= "Aminu Ibrahim", 'DASHVOLT REVENUE SCHEDULE'!G9, 0) -> 0 | G8: =IF('DASHVOLT REVENUE SCHEDULE'!D9= "Bello Saulawa",'DASHVOLT REVENUE SCHEDULE'!G9, 0) -> 2500 | H8: =IF('DASHVOLT REVENUE SCHEDULE'!D9= "Murtala Hassan", 'DASHVOLT REVENUE SCHEDULE'!G9, 0) -> 0 | I8: =IF('DASHVOLT REVENUE SCHEDULE'!D9= "Babangida Monde", 'DASHVOLT REVENUE SCHEDULE'!G9, 0) -> 0 | J8: =IF('DASHVOLT REVENUE SCHEDULE'!D9= "Bello Abdullahi", 'DASHVOLT REVENUE SCHEDULE'!G9, 0) -> 0
B9: ='DASHVOLT REVENUE SCHEDULE'!B10 -> 45900 | C9: ='DASHVOLT REVENUE SCHEDULE'!C10 -> 0 | D9: ='DASHVOLT REVENUE SCHEDULE'!E10 -> COMPLETED | E9: ='DASHVOLT REVENUE SCHEDULE'!F10 -> Dawaki | F9: =IF('DASHVOLT REVENUE SCHEDULE'!D10= "Aminu Ibrahim", 'DASHVOLT REVENUE SCHEDULE'!G10, 0) -> 0 | G9: =IF('DASHVOLT REVENUE SCHEDULE'!D10= "Bello Saulawa",'DASHVOLT REVENUE SCHEDULE'!G10, 0) -> 2900 | H9: =IF('DASHVOLT REVENUE SCHEDULE'!D10= "Murtala Hassan", 'DASHVOLT REVENUE SCHEDULE'!G10, 0) -> 0 | I9: =IF('DASHVOLT REVENUE SCHEDULE'!D10= "Babangida Monde", 'DASHVOLT REVENUE SCHEDULE'!G10, 0) -> 0 | J9: =IF('DASHVOLT REVENUE SCHEDULE'!D10= "Bello Abdullahi", 'DASHVOLT REVENUE SCHEDULE'!G10, 0) -> 0
B10: ='DASHVOLT REVENUE SCHEDULE'!B11 -> 45900 | C10: ='DASHVOLT REVENUE SCHEDULE'!C11 -> 0 | D10: ='DASHVOLT REVENUE SCHEDULE'!E11 -> COMPLETED | E10: ='DASHVOLT REVENUE SCHEDULE'!F11 -> Jabi | F10: =IF('DASHVOLT REVENUE SCHEDULE'!D11= "Aminu Ibrahim", 'DASHVOLT REVENUE SCHEDULE'!G11, 0) -> 0 | G10: =IF('DASHVOLT REVENUE SCHEDULE'!D11= "Bello Saulawa",'DASHVOLT REVENUE SCHEDULE'!G11, 0) -> 2500 | H10: =IF('DASHVOLT REVENUE SCHEDULE'!D11= "Murtala Hassan", 'DASHVOLT REVENUE SCHEDULE'!G11, 0) -> 0 | I10: =IF('DASHVOLT REVENUE SCHEDULE'!D11= "Babangida Monde", 'DASHVOLT REVENUE SCHEDULE'!G11, 0) -> 0 | J10: =IF('DASHVOLT REVENUE SCHEDULE'!D11= "Bello Abdullahi", 'DASHVOLT REVENUE SCHEDULE'!G11, 0) -> 0
B11: ='DASHVOLT REVENUE SCHEDULE'!B12 -> 45900 | C11: ='DASHVOLT REVENUE SCHEDULE'!C12 -> 0 | D11: ='DASHVOLT REVENUE SCHEDULE'!E12 -> COMPLETED | E11: ='DASHVOLT REVENUE SCHEDULE'!F12 -> Dawaki | F11: =IF('DASHVOLT REVENUE SCHEDULE'!D12= "Aminu Ibrahim", 'DASHVOLT REVENUE SCHEDULE'!G12, 0) -> 0 | G11: =IF('DASHVOLT REVENUE SCHEDULE'!D12= "Bello Saulawa",'DASHVOLT REVENUE SCHEDULE'!G12, 0) -> 2900 | H11: =IF('DASHVOLT REVENUE SCHEDULE'!D12= "Murtala Hassan", 'DASHVOLT REVENUE SCHEDULE'!G12, 0) -> 0 | I11: =IF('DASHVOLT REVENUE SCHEDULE'!D12= "Babangida Monde", 'DASHVOLT REVENUE SCHEDULE'!G12, 0) -> 0 | J11: =IF('DASHVOLT REVENUE SCHEDULE'!D12= "Bello Abdullahi", 'DASHVOLT REVENUE SCHEDULE'!G12, 0) -> 0
B12: ='DASHVOLT REVENUE SCHEDULE'!B13 -> 45900 | C12: ='DASHVOLT REVENUE SCHEDULE'!C13 -> 0 | D12: ='DASHVOLT REVENUE SCHEDULE'!E13 -> COMPLETED | E12: ='DASHVOLT REVENUE SCHEDULE'!F13 -> Wuse2 | F12: =IF('DASHVOLT REVENUE SCHEDULE'!D13= "Aminu Ibrahim", 'DASHVOLT REVENUE SCHEDULE'!G13, 0) -> 0 | G12: =IF('DASHVOLT REVENUE SCHEDULE'!D13= "Bello Saulawa",'DASHVOLT REVENUE SCHEDULE'!G13, 0) -> 0 | H12: =IF('DASHVOLT REVENUE SCHEDULE'!D13= "Murtala Hassan", 'DASHVOLT REVENUE SCHEDULE'!G13, 0) -> 2500 | I12: =IF('DASHVOLT REVENUE SCHEDULE'!D13= "Babangida Monde", 'DASHVOLT REVENUE SCHEDULE'!G13, 0) -> 0 | J12: =IF('DASHVOLT REVENUE SCHEDULE'!D13= "Bello Abdullahi", 'DASHVOLT REVENUE SCHEDULE'!G13, 0) -> 0 | L12: =SUM(G6:G35) -> 34800
B13: ='DASHVOLT REVENUE SCHEDULE'!B14 -> 45900 | C13: ='DASHVOLT REVENUE SCHEDULE'!C14 -> 0 | D13: ='DASHVOLT REVENUE SCHEDULE'!E14 -> COMPLETED | E13: ='DASHVOLT REVENUE SCHEDULE'!F14 -> Utako | F13: =IF('DASHVOLT REVENUE SCHEDULE'!D14= "Aminu Ibrahim", 'DASHVOLT REVENUE SCHEDULE'!G14, 0) -> 0 | G13: =IF('DASHVOLT REVENUE SCHEDULE'!D14= "Bello Saulawa",'DASHVOLT REVENUE SCHEDULE'!G14, 0) -> 0 | H13: =IF('DASHVOLT REVENUE SCHEDULE'!D14= "Murtala Hassan", 'DASHVOLT REVENUE SCHEDULE'!G14, 0) -> 2500 | I13: =IF('DASHVOLT REVENUE SCHEDULE'!D14= "Babangida Monde", 'DASHVOLT REVENUE SCHEDULE'!G14, 0) -> 0 | J13: =IF('DASHVOLT REVENUE SCHEDULE'!D14= "Bello Abdullahi", 'DASHVOLT REVENUE SCHEDULE'!G14, 0) -> 0
B14: ='DASHVOLT REVENUE SCHEDULE'!B15 -> 45900 | C14: ='DASHVOLT REVENUE SCHEDULE'!C15 -> 0 | D14: ='DASHVOLT REVENUE SCHEDULE'!E15 -> COMPLETED | E14: ='DASHVOLT REVENUE SCHEDULE'!F15 -> Life camp | F14: =IF('DASHVOLT REVENUE SCHEDULE'!D15= "Aminu Ibrahim", 'DASHVOLT REVENUE SCHEDULE'!G15, 0) -> 0 | G14: =IF('DASHVOLT REVENUE SCHEDULE'!D15= "Bello Saulawa",'DASHVOLT REVENUE SCHEDULE'!G15, 0) -> 0 | H14: =IF('DASHVOLT REVENUE SCHEDULE'!D15= "Murtala Hassan", 'DASHVOLT REVENUE SCHEDULE'!G15, 0) -> 2200 | I14: =IF('DASHVOLT REVENUE SCHEDULE'!D15= "Babangida Monde", 'DASHVOLT REVENUE SCHEDULE'!G15, 0) -> 0 | J14: =IF('DASHVOLT REVENUE SCHEDULE'!D15= "Bello Abdullahi", 'DASHVOLT REVENUE SCHEDULE'!G15, 0) -> 0
B15: ='DASHVOLT REVENUE SCHEDULE'!B16 -> 45900 | C15: ='DASHVOLT REVENUE SCHEDULE'!C16 -> 0 | D15: ='DASHVOLT REVENUE SCHEDULE'!E16 -> COMPLETED | E15: ='DASHVOLT REVENUE SCHEDULE'!F16 -> Kado | F15: =IF('DASHVOLT REVENUE SCHEDULE'!D16= "Aminu Ibrahim", 'DASHVOLT REVENUE SCHEDULE'!G16, 0) -> 0 | G15: =IF('DASHVOLT REVENUE SCHEDULE'!D16= "Bello Saulawa",'DASHVOLT REVENUE SCHEDULE'!G16, 0) -> 0 | H15: =IF('DASHVOLT REVENUE SCHEDULE'!D16= "Murtala Hassan", 'DASHVOLT REVENUE SCHEDULE'!G16, 0) -> 1700 | I15: =IF('DASHVOLT REVENUE SCHEDULE'!D16= "Babangida Monde", 'DASHVOLT REVENUE SCHEDULE'!G16, 0) -> 0 | J15: =IF('DASHVOLT REVENUE SCHEDULE'!D16= "Bello Abdullahi", 'DASHVOLT REVENUE SCHEDULE'!G16, 0) -> 0
B16: ='DASHVOLT REVENUE SCHEDULE'!B17 -> 45900 | C16: ='DASHVOLT REVENUE SCHEDULE'!C17 -> 0 | D16: ='DASHVOLT REVENUE SCHEDULE'!E17 -> COMPLETED | E16: ='DASHVOLT REVENUE SCHEDULE'!F17 -> Wuse2 | F16: =IF('DASHVOLT REVENUE SCHEDULE'!D17= "Aminu Ibrahim", 'DASHVOLT REVENUE SCHEDULE'!G17, 0) -> 0 | G16: =IF('DASHVOLT REVENUE SCHEDULE'!D17= "Bello Saulawa",'DASHVOLT REVENUE SCHEDULE'!G17, 0) -> 0 | H16: =IF('DASHVOLT REVENUE SCHEDULE'!D17= "Murtala Hassan", 'DASHVOLT REVENUE SCHEDULE'!G17, 0) -> 0 | I16: =IF('DASHVOLT REVENUE SCHEDULE'!D17= "Babangida Monde", 'DASHVOLT REVENUE SCHEDULE'!G17, 0) -> 0 | J16: =IF('DASHVOLT REVENUE SCHEDULE'!D17= "Bello Abdullahi", 'DASHVOLT REVENUE SCHEDULE'!G17, 0) -> 2500
B17: ='DASHVOLT REVENUE SCHEDULE'!B18 -> 45900 | C17: ='DASHVOLT REVENUE SCHEDULE'!C18 -> 0 | D17: ='DASHVOLT REVENUE SCHEDULE'!E18 -> COMPLETED | E17: ='DASHVOLT REVENUE SCHEDULE'!F18 -> Kado | F17: =IF('DASHVOLT REVENUE SCHEDULE'!D18= "Aminu Ibrahim", 'DASHVOLT REVENUE SCHEDULE'!G18, 0) -> 0 | G17: =IF('DASHVOLT REVENUE SCHEDULE'!D18= "Bello Saulawa",'DASHVOLT REVENUE SCHEDULE'!G18, 0) -> 0 | H17: =IF('DASHVOLT REVENUE SCHEDULE'!D18= "Murtala Hassan", 'DASHVOLT REVENUE SCHEDULE'!G18, 0) -> 0 | I17: =IF('DASHVOLT REVENUE SCHEDULE'!D18= "Babangida Monde", 'DASHVOLT REVENUE SCHEDULE'!G18, 0) -> 0 | J17: =IF('DASHVOLT REVENUE SCHEDULE'!D18= "Bello Abdullahi", 'DASHVOLT REVENUE SCHEDULE'!G18, 0) -> 1700
B18: ='DASHVOLT REVENUE SCHEDULE'!B19 -> 45900 | C18: ='DASHVOLT REVENUE SCHEDULE'!C19 -> 0 | D18: ='DASHVOLT REVENUE SCHEDULE'!E19 -> COMPLETED | E18: ='DASHVOLT REVENUE SCHEDULE'!F19 -> Mitama | F18: =IF('DASHVOLT REVENUE SCHEDULE'!D19= "Aminu Ibrahim", 'DASHVOLT REVENUE SCHEDULE'!G19, 0) -> 0 | G18: =IF('DASHVOLT REVENUE SCHEDULE'!D19= "Bello Saulawa",'DASHVOLT REVENUE SCHEDULE'!G19, 0) -> 0 | H18: =IF('DASHVOLT REVENUE SCHEDULE'!D19= "Murtala Hassan", 'DASHVOLT REVENUE SCHEDULE'!G19, 0) -> 0 | I18: =IF('DASHVOLT REVENUE SCHEDULE'!D19= "Babangida Monde", 'DASHVOLT REVENUE SCHEDULE'!G19, 0) -> 0 | J18: =IF('DASHVOLT REVENUE SCHEDULE'!D19= "Bello Abdullahi", 'DASHVOLT REVENUE SCHEDULE'!G19, 0) -> 2500
B19: ='DASHVOLT REVENUE SCHEDULE'!B20 -> 45900 | C19: ='DASHVOLT REVENUE SCHEDULE'!C20 -> 0 | D19: ='DASHVOLT REVENUE SCHEDULE'!E20 -> COMPLETED | E19: ='DASHVOLT REVENUE SCHEDULE'!F20 -> Wuse2 | F19: =IF('DASHVOLT REVENUE SCHEDULE'!D20= "Aminu Ibrahim", 'DASHVOLT REVENUE SCHEDULE'!G20, 0) -> 0 | G19: =IF('DASHVOLT REVENUE SCHEDULE'!D20= "Bello Saulawa",'DASHVOLT REVENUE SCHEDULE'!G20, 0) -> 0 | H19: =IF('DASHVOLT REVENUE SCHEDULE'!D20= "Murtala Hassan", 'DASHVOLT REVENUE SCHEDULE'!G20, 0) -> 0 | I19: =IF('DASHVOLT REVENUE SCHEDULE'!D20= "Babangida Monde", 'DASHVOLT REVENUE SCHEDULE'!G20, 0) -> 0 | J19: =IF('DASHVOLT REVENUE SCHEDULE'!D20= "Bello Abdullahi", 'DASHVOLT REVENUE SCHEDULE'!G20, 0) -> 2500
B20: ='DASHVOLT REVENUE SCHEDULE'!B21 -> 45901 | C20: ='DASHVOLT REVENUE SCHEDULE'!C21 -> 0 | D20: ='DASHVOLT REVENUE SCHEDULE'!E21 -> COMPLETED | E20: ='DASHVOLT REVENUE SCHEDULE'!F21 -> Guzape | F20: =IF('DASHVOLT REVENUE SCHEDULE'!D21= "Aminu Ibrahim", 'DASHVOLT REVENUE SCHEDULE'!G21, 0) -> 0 | G20: =IF('DASHVOLT REVENUE SCHEDULE'!D21= "Bello Saulawa",'DASHVOLT REVENUE SCHEDULE'!G21, 0) -> 3200 | H20: =IF('DASHVOLT REVENUE SCHEDULE'!D21= "Murtala Hassan", 'DASHVOLT REVENUE SCHEDULE'!G21, 0) -> 0 | I20: =IF('DASHVOLT REVENUE SCHEDULE'!D21= "Babangida Monde", 'DASHVOLT REVENUE SCHEDULE'!G21, 0) -> 0 | J20: =IF('DASHVOLT REVENUE SCHEDULE'!D21= "Bello Abdullahi", 'DASHVOLT REVENUE SCHEDULE'!G21, 0) -> 0
B21: ='DASHVOLT REVENUE SCHEDULE'!B22 -> 45901 | C21: ='DASHVOLT REVENUE SCHEDULE'!C22 -> 0 | D21: ='DASHVOLT REVENUE SCHEDULE'!E22 -> COMPLETED | E21: ='DASHVOLT REVENUE SCHEDULE'!F22 -> Jabi | F21: =IF('DASHVOLT REVENUE SCHEDULE'!D22= "Aminu Ibrahim", 'DASHVOLT REVENUE SCHEDULE'!G22, 0) -> 0 | G21: =IF('DASHVOLT REVENUE SCHEDULE'!D22= "Bello Saulawa",'DASHVOLT REVENUE SCHEDULE'!G22, 0) -> 2500 | H21: =IF('DASHVOLT REVENUE SCHEDULE'!D22= "Murtala Hassan", 'DASHVOLT REVENUE SCHEDULE'!G22, 0) -> 0 | I21: =IF('DASHVOLT REVENUE SCHEDULE'!D22= "Babangida Monde", 'DASHVOLT REVENUE SCHEDULE'!G22, 0) -> 0 | J21: =IF('DASHVOLT REVENUE SCHEDULE'!D22= "Bello Abdullahi", 'DASHVOLT REVENUE SCHEDULE'!G22, 0) -> 0
B22: ='DASHVOLT REVENUE SCHEDULE'!B23 -> 45901 | C22: ='DASHVOLT REVENUE SCHEDULE'!C23 -> 0 | D22: ='DASHVOLT REVENUE SCHEDULE'!E23 -> COMPLETED | E22: ='DASHVOLT REVENUE SCHEDULE'!F23 -> CBD | F22: =IF('DASHVOLT REVENUE SCHEDULE'!D23= "Aminu Ibrahim", 'DASHVOLT REVENUE SCHEDULE'!G23, 0) -> 0 | G22: =IF('DASHVOLT REVENUE SCHEDULE'!D23= "Bello Saulawa",'DASHVOLT REVENUE SCHEDULE'!G23, 0) -> 2700 | H22: =IF('DASHVOLT REVENUE SCHEDULE'!D23= "Murtala Hassan", 'DASHVOLT REVENUE SCHEDULE'!G23, 0) -> 0 | I22: =IF('DASHVOLT REVENUE SCHEDULE'!D23= "Babangida Monde", 'DASHVOLT REVENUE SCHEDULE'!G23, 0) -> 0 | J22: =IF('DASHVOLT REVENUE SCHEDULE'!D23= "Bello Abdullahi", 'DASHVOLT REVENUE SCHEDULE'!G23, 0) -> 0
B23: ='DASHVOLT REVENUE SCHEDULE'!B24 -> 45901 | C23: ='DASHVOLT REVENUE SCHEDULE'!C24 -> 0 | D23: ='DASHVOLT REVENUE SCHEDULE'!E24 -> COMPLETED | E23: ='DASHVOLT REVENUE SCHEDULE'!F24 -> Garki | F23: =IF('DASHVOLT REVENUE SCHEDULE'!D24= "Aminu Ibrahim", 'DASHVOLT REVENUE SCHEDULE'!G24, 0) -> 0 | G23: =IF('DASHVOLT REVENUE SCHEDULE'!D24= "Bello Saulawa",'DASHVOLT REVENUE SCHEDULE'!G24, 0) -> 3000 | H23: =IF('DASHVOLT REVENUE SCHEDULE'!D24= "Murtala Hassan", 'DASHVOLT REVENUE SCHEDULE'!G24, 0) -> 0 | I23: =IF('DASHVOLT REVENUE SCHEDULE'!D24= "Babangida Monde", 'DASHVOLT REVENUE SCHEDULE'!G24, 0) -> 0 | J23: =IF('DASHVOLT REVENUE SCHEDULE'!D24= "Bello Abdullahi", 'DASHVOLT REVENUE SCHEDULE'!G24, 0) -> 0
B24: ='DASHVOLT REVENUE SCHEDULE'!B25 -> 45901 | C24: ='DASHVOLT REVENUE SCHEDULE'!C25 -> 0 | D24: ='DASHVOLT REVENUE SCHEDULE'!E25 -> COMPLETED | E24: ='DASHVOLT REVENUE SCHEDULE'!F25 -> Jabi | F24: =IF('DASHVOLT REVENUE SCHEDULE'!D25= "Aminu Ibrahim", 'DASHVOLT REVENUE SCHEDULE'!G25, 0) -> 0 | G24: =IF('DASHVOLT REVENUE SCHEDULE'!D25= "Bello Saulawa",'DASHVOLT REVENUE SCHEDULE'!G25, 0) -> 2500 | H24: =IF('DASHVOLT REVENUE SCHEDULE'!D25= "Murtala Hassan", 'DASHVOLT REVENUE SCHEDULE'!G25, 0) -> 0 | I24: =IF('DASHVOLT REVENUE SCHEDULE'!D25= "Babangida Monde", 'DASHVOLT REVENUE SCHEDULE'!G25, 0) -> 0 | J24: =IF('DASHVOLT REVENUE SCHEDULE'!D25= "Bello Abdullahi", 'DASHVOLT REVENUE SCHEDULE'!G25, 0) -> 0
... B30: ='DASHVOLT REVENUE SCHEDULE'!B31 -> 45901 | C30: ='DASHVOLT REVENUE SCHEDULE'!C31 -> 0 | D30: ='DASHVOLT REVENUE SCHEDULE'!E31 -> COMPLETED | E30: ='DASHVOLT REVENUE SCHEDULE'!F31 -> Life camp | F30: =IF('DASHVOLT REVENUE SCHEDULE'!D31= "Aminu Ibrahim", 'DASHVOLT REVENUE SCHEDULE'!G31, 0) -> 0 | G30: =IF('DASHVOLT REVENUE SCHEDULE'!D31= "Bello Saulawa",'DASHVOLT REVENUE SCHEDULE'!G31, 0) -> 0 | H30: =IF('DASHVOLT REVENUE SCHEDULE'!D31= "Murtala Hassan", 'DASHVOLT REVENUE SCHEDULE'!G31, 0) -> 0 | I30: =IF('DASHVOLT REVENUE SCHEDULE'!D31= "Babangida Monde", 'DASHVOLT REVENUE SCHEDULE'!G31, 0) -> 0 | J30: =IF('DASHVOLT REVENUE SCHEDULE'!D31= "Bello Abdullahi", 'DASHVOLT REVENUE SCHEDULE'!G31, 0) -> 2200
B31: ='DASHVOLT REVENUE SCHEDULE'!B30 -> 45901 | C31: ='DASHVOLT REVENUE SCHEDULE'!C30 -> 0 | D31: ='DASHVOLT REVENUE SCHEDULE'!E30 -> COMPLETED | E31: ='DASHVOLT REVENUE SCHEDULE'!F30 -> Gwarimpa | F31: =IF('DASHVOLT REVENUE SCHEDULE'!D30= "Aminu Ibrahim", 'DASHVOLT REVENUE SCHEDULE'!G30, 0) -> 0 | G31: =IF('DASHVOLT REVENUE SCHEDULE'!D30= "Bello Saulawa",'DASHVOLT REVENUE SCHEDULE'!G30, 0) -> 0 | H31: =IF('DASHVOLT REVENUE SCHEDULE'!D30= "Murtala Hassan", 'DASHVOLT REVENUE SCHEDULE'!G30, 0) -> 0 | I31: =IF('DASHVOLT REVENUE SCHEDULE'!D30= "Babangida Monde", 'DASHVOLT REVENUE SCHEDULE'!G30, 0) -> 0 | J31: =IF('DASHVOLT REVENUE SCHEDULE'!D30= "Bello Abdullahi", 'DASHVOLT REVENUE SCHEDULE'!G30, 0) -> 2700
B32: ='DASHVOLT REVENUE SCHEDULE'!B31 -> 45901 | C32: ='DASHVOLT REVENUE SCHEDULE'!C31 -> 0 | D32: ='DASHVOLT REVENUE SCHEDULE'!E31 -> COMPLETED | E32: ='DASHVOLT REVENUE SCHEDULE'!F31 -> Life camp | F32: =IF('DASHVOLT REVENUE SCHEDULE'!D31= "Aminu Ibrahim", 'DASHVOLT REVENUE SCHEDULE'!G31, 0) -> 0 | G32: =IF('DASHVOLT REVENUE SCHEDULE'!D31= "Bello Saulawa",'DASHVOLT REVENUE SCHEDULE'!G31, 0) -> 0 | H32: =IF('DASHVOLT REVENUE SCHEDULE'!D31= "Murtala Hassan", 'DASHVOLT REVENUE SCHEDULE'!G31, 0) -> 0 | I32: =IF('DASHVOLT REVENUE SCHEDULE'!D31= "Babangida Monde", 'DASHVOLT REVENUE SCHEDULE'!G31, 0) -> 0 | J32: =IF('DASHVOLT REVENUE SCHEDULE'!D31= "Bello Abdullahi", 'DASHVOLT REVENUE SCHEDULE'!G31, 0) -> 2200
B33: ='DASHVOLT REVENUE SCHEDULE'!B32 -> 45901 | C33: ='DASHVOLT REVENUE SCHEDULE'!C32 -> 0 | D33: ='DASHVOLT REVENUE SCHEDULE'!E32 -> COMPLETED | E33: ='DASHVOLT REVENUE SCHEDULE'!F32 -> mabushi | F33: =IF('DASHVOLT REVENUE SCHEDULE'!D32= "Aminu Ibrahim", 'DASHVOLT REVENUE SCHEDULE'!G32, 0) -> 0 | G33: =IF('DASHVOLT REVENUE SCHEDULE'!D32= "Bello Saulawa",'DASHVOLT REVENUE SCHEDULE'!G32, 0) -> 0 | H33: =IF('DASHVOLT REVENUE SCHEDULE'!D32= "Murtala Hassan", 'DASHVOLT REVENUE SCHEDULE'!G32, 0) -> 0 | I33: =IF('DASHVOLT REVENUE SCHEDULE'!D32= "Babangida Monde", 'DASHVOLT REVENUE SCHEDULE'!G32, 0) -> 0 | J33: =IF('DASHVOLT REVENUE SCHEDULE'!D32= "Bello Abdullahi", 'DASHVOLT REVENUE SCHEDULE'!G32, 0) -> 2200
B34: ='DASHVOLT REVENUE SCHEDULE'!B33 -> 45901 | C34: ='DASHVOLT REVENUE SCHEDULE'!C33 -> 0 | D34: ='DASHVOLT REVENUE SCHEDULE'!E33 -> COMPLETED | E34: ='DASHVOLT REVENUE SCHEDULE'!F33 -> Jahi | F34: =IF('DASHVOLT REVENUE SCHEDULE'!D33= "Aminu Ibrahim", 'DASHVOLT REVENUE SCHEDULE'!G33, 0) -> 0 | G34: =IF('DASHVOLT REVENUE SCHEDULE'!D33= "Bello Saulawa",'DASHVOLT REVENUE SCHEDULE'!G33, 0) -> 0 | H34: =IF('DASHVOLT REVENUE SCHEDULE'!D33= "Murtala Hassan", 'DASHVOLT REVENUE SCHEDULE'!G33, 0) -> 0 | I34: =IF('DASHVOLT REVENUE SCHEDULE'!D33= "Babangida Monde", 'DASHVOLT REVENUE SCHEDULE'!G33, 0) -> 0 | J34: =IF('DASHVOLT REVENUE SCHEDULE'!D33= "Bello Abdullahi", 'DASHVOLT REVENUE SCHEDULE'!G33, 0) -> 2200
B35: ='DASHVOLT REVENUE SCHEDULE'!B34 -> 45901 | C35: ='DASHVOLT REVENUE SCHEDULE'!C34 -> 0 | D35: ='DASHVOLT REVENUE SCHEDULE'!E34 -> COMPLETED | E35: ='DASHVOLT REVENUE SCHEDULE'!F34 -> Wuye | F35: =IF('DASHVOLT REVENUE SCHEDULE'!D34= "Aminu Ibrahim", 'DASHVOLT REVENUE SCHEDULE'!G34, 0) -> 0 | G35: =IF('DASHVOLT REVENUE SCHEDULE'!D34= "Bello Saulawa",'DASHVOLT REVENUE SCHEDULE'!G34, 0) -> 2200 | H35: =IF('DASHVOLT REVENUE SCHEDULE'!D34= "Murtala Hassan", 'DASHVOLT REVENUE SCHEDULE'!G34, 0) -> 0 | I35: =IF('DASHVOLT REVENUE SCHEDULE'!D34= "Babangida Monde", 'DASHVOLT REVENUE SCHEDULE'!G34, 0) -> 0 | J35: =IF('DASHVOLT REVENUE SCHEDULE'!D34= "Bello Abdullahi", 'DASHVOLT REVENUE SCHEDULE'!G34, 0) -> 0
B36: ='DASHVOLT REVENUE SCHEDULE'!B37 -> 45902 | C36: ='DASHVOLT REVENUE SCHEDULE'!C37 -> 0 | D36: ='DASHVOLT REVENUE SCHEDULE'!E37 -> COMPLETED | E36: ='DASHVOLT REVENUE SCHEDULE'!F37 -> Asokoro | F36: =IF('DASHVOLT REVENUE SCHEDULE'!D37= "Aminu Ibrahim", 'DASHVOLT REVENUE SCHEDULE'!G37, 0) -> 0 | G36: =IF('DASHVOLT REVENUE SCHEDULE'!D37= "Bello Saulawa",'DASHVOLT REVENUE SCHEDULE'!G37, 0) -> 3200 | H36: =IF('DASHVOLT REVENUE SCHEDULE'!D37= "Murtala Hassan", 'DASHVOLT REVENUE SCHEDULE'!G37, 0) -> 0 | I36: =IF('DASHVOLT REVENUE SCHEDULE'!D37= "Babangida Monde", 'DASHVOLT REVENUE SCHEDULE'!G37, 0) -> 0 | J36: =IF('DASHVOLT REVENUE SCHEDULE'!D37= "Bello Abdullahi", 'DASHVOLT REVENUE SCHEDULE'!G37, 0) -> 0
B37: ='DASHVOLT REVENUE SCHEDULE'!B38 -> 45902 | C37: ='DASHVOLT REVENUE SCHEDULE'!C38 -> 0 | D37: ='DASHVOLT REVENUE SCHEDULE'!E38 -> COMPLETED | E37: ='DASHVOLT REVENUE SCHEDULE'!F38 -> Life camp | F37: =IF('DASHVOLT REVENUE SCHEDULE'!D38= "Aminu Ibrahim", 'DASHVOLT REVENUE SCHEDULE'!G38, 0) -> 0 | G37: =IF('DASHVOLT REVENUE SCHEDULE'!D38= "Bello Saulawa",'DASHVOLT REVENUE SCHEDULE'!G38, 0) -> 0 | H37: =IF('DASHVOLT REVENUE SCHEDULE'!D38= "Murtala Hassan", 'DASHVOLT REVENUE SCHEDULE'!G38, 0) -> 0 | I37: =IF('DASHVOLT REVENUE SCHEDULE'!D38= "Babangida Monde", 'DASHVOLT REVENUE SCHEDULE'!G38, 0) -> 0 | J37: =IF('DASHVOLT REVENUE SCHEDULE'!D38= "Bello Abdullahi", 'DASHVOLT REVENUE SCHEDULE'!G38, 0) -> 2200
B38: ='DASHVOLT REVENUE SCHEDULE'!B39 -> 45902 | C38: ='DASHVOLT REVENUE SCHEDULE'!C39 -> 0 | D38: ='DASHVOLT REVENUE SCHEDULE'!E39 -> COMPLETED | E38: ='DASHVOLT REVENUE SCHEDULE'!F39 -> Jahi | F38: =IF('DASHVOLT REVENUE SCHEDULE'!D39= "Aminu Ibrahim", 'DASHVOLT REVENUE SCHEDULE'!G39, 0) -> 0 | G38: =IF('DASHVOLT REVENUE SCHEDULE'!D39= "Bello Saulawa",'DASHVOLT REVENUE SCHEDULE'!G39, 0) -> 0 | H38: =IF('DASHVOLT REVENUE SCHEDULE'!D39= "Murtala Hassan", 'DASHVOLT REVENUE SCHEDULE'!G39, 0) -> 2200 | I38: =IF('DASHVOLT REVENUE SCHEDULE'!D39= "Babangida Monde", 'DASHVOLT REVENUE SCHEDULE'!G39, 0) -> 0 | J38: =IF('DASHVOLT REVENUE SCHEDULE'!D39= "Bello Abdullahi", 'DASHVOLT REVENUE SCHEDULE'!G39, 0) -> 0
B39: ='DASHVOLT REVENUE SCHEDULE'!B40 -> 45902 | C39: ='DASHVOLT REVENUE SCHEDULE'!C40 -> 0 | D39: ='DASHVOLT REVENUE SCHEDULE'!E40 -> COMPLETED | E39: ='DASHVOLT REVENUE SCHEDULE'!F40 -> Wuye | F39: =IF('DASHVOLT REVENUE SCHEDULE'!D40= "Aminu Ibrahim", 'DASHVOLT REVENUE SCHEDULE'!G40, 0) -> 0 | G39: =IF('DASHVOLT REVENUE SCHEDULE'!D40= "Bello Saulawa",'DASHVOLT REVENUE SCHEDULE'!G40, 0) -> 0 | H39: =IF('DASHVOLT REVENUE SCHEDULE'!D40= "Murtala Hassan", 'DASHVOLT REVENUE SCHEDULE'!G40, 0) -> 2500 | I39: =IF('DASHVOLT REVENUE SCHEDULE'!D40= "Babangida Monde", 'DASHVOLT REVENUE SCHEDULE'!G40, 0) -> 0 | J39: =IF('DASHVOLT REVENUE SCHEDULE'!D40= "Bello Abdullahi", 'DASHVOLT REVENUE SCHEDULE'!G40, 0) -> 0
B40: ='DASHVOLT REVENUE SCHEDULE'!B41 -> 45902 | C40: ='DASHVOLT REVENUE SCHEDULE'!C41 -> 0 | D40: ='DASHVOLT REVENUE SCHEDULE'!E41 -> COMPLETED | E40: ='DASHVOLT REVENUE SCHEDULE'!F41 -> Jahi | F40: =IF('DASHVOLT REVENUE SCHEDULE'!D41= "Aminu Ibrahim", 'DASHVOLT REVENUE SCHEDULE'!G41, 0) -> 0 | G40: =IF('DASHVOLT REVENUE SCHEDULE'!D41= "Bello Saulawa",'DASHVOLT REVENUE SCHEDULE'!G41, 0) -> 0 | H40: =IF('DASHVOLT REVENUE SCHEDULE'!D41= "Murtala Hassan", 'DASHVOLT REVENUE SCHEDULE'!G41, 0) -> 0 | I40: =IF('DASHVOLT REVENUE SCHEDULE'!D41= "Babangida Monde", 'DASHVOLT REVENUE SCHEDULE'!G41, 0) -> 0 | J40: =IF('DASHVOLT REVENUE SCHEDULE'!D41= "Bello Abdullahi", 'DASHVOLT REVENUE SCHEDULE'!G41, 0) -> 2200
B41: ='DASHVOLT REVENUE SCHEDULE'!B42 -> 45902 | C41: ='DASHVOLT REVENUE SCHEDULE'!C42 -> 0 | D41: ='DASHVOLT REVENUE SCHEDULE'!E42 -> COMPLETED | E41: ='DASHVOLT REVENUE SCHEDULE'!F42 -> CBD | F41: =IF('DASHVOLT REVENUE SCHEDULE'!D42= "Aminu Ibrahim", 'DASHVOLT REVENUE SCHEDULE'!G42, 0) -> 0 | G41: =IF('DASHVOLT REVENUE SCHEDULE'!D42= "Bello Saulawa",'DASHVOLT REVENUE SCHEDULE'!G42, 0) -> 2700 | H41: =IF('DASHVOLT REVENUE SCHEDULE'!D42= "Murtala Hassan", 'DASHVOLT REVENUE SCHEDULE'!G42, 0) -> 0 | I41: =IF('DASHVOLT REVENUE SCHEDULE'!D42= "Babangida Monde", 'DASHVOLT REVENUE SCHEDULE'!G42, 0) -> 0 | J41: =IF('DASHVOLT REVENUE SCHEDULE'!D42= "Bello Abdullahi", 'DASHVOLT REVENUE SCHEDULE'!G42, 0) -> 0
B42: ='DASHVOLT REVENUE SCHEDULE'!B43 -> 45902 | C42: ='DASHVOLT REVENUE SCHEDULE'!C43 -> 0 | D42: ='DASHVOLT REVENUE SCHEDULE'!E43 -> COMPLETED | E42: ='DASHVOLT REVENUE SCHEDULE'!F43 -> Lokogoma | F42: =IF('DASHVOLT REVENUE SCHEDULE'!D43= "Aminu Ibrahim", 'DASHVOLT REVENUE SCHEDULE'!G43, 0) -> 0 | G42: =IF('DASHVOLT REVENUE SCHEDULE'!D43= "Bello Saulawa",'DASHVOLT REVENUE SCHEDULE'!G43, 0) -> 4000 | H42: =IF('DASHVOLT REVENUE SCHEDULE'!D43= "Murtala Hassan", 'DASHVOLT REVENUE SCHEDULE'!G43, 0) -> 0 | I42: =IF('DASHVOLT REVENUE SCHEDULE'!D43= "Babangida Monde", 'DASHVOLT REVENUE SCHEDULE'!G43, 0) -> 0 | J42: =IF('DASHVOLT REVENUE SCHEDULE'!D43= "Bello Abdullahi", 'DASHVOLT REVENUE SCHEDULE'!G43, 0) -> 0
B43: ='DASHVOLT REVENUE SCHEDULE'!B44 -> 45902 | C43: ='DASHVOLT REVENUE SCHEDULE'!C44 -> 0 | D43: ='DASHVOLT REVENUE SCHEDULE'!E44 -> COMPLETED | E43: ='DASHVOLT REVENUE SCHEDULE'!F44 -> Kado | F43: =IF('DASHVOLT REVENUE SCHEDULE'!D44= "Aminu Ibrahim", 'DASHVOLT REVENUE SCHEDULE'!G44, 0) -> 0 | G43: =IF('DASHVOLT REVENUE SCHEDULE'!D44= "Bello Saulawa",'DASHVOLT REVENUE SCHEDULE'!G44, 0) -> 0 | H43: =IF('DASHVOLT REVENUE SCHEDULE'!D44= "Murtala Hassan", 'DASHVOLT REVENUE SCHEDULE'!G44, 0) -> 0 | I43: =IF('DASHVOLT REVENUE SCHEDULE'!D44= "Babangida Monde", 'DASHVOLT REVENUE SCHEDULE'!G44, 0) -> 0 | J43: =IF('DASHVOLT REVENUE SCHEDULE'!D44= "Bello Abdullahi", 'DASHVOLT REVENUE SCHEDULE'!G44, 0) -> 1700
B44: ='DASHVOLT REVENUE SCHEDULE'!B45 -> 45902 | C44: ='DASHVOLT REVENUE SCHEDULE'!C45 -> 0 | D44: ='DASHVOLT REVENUE SCHEDULE'!E45 -> COMPLETED | E44: ='DASHVOLT REVENUE SCHEDULE'!F45 -> CBD | F44: =IF('DASHVOLT REVENUE SCHEDULE'!D45= "Aminu Ibrahim", 'DASHVOLT REVENUE SCHEDULE'!G45, 0) -> 0 | G44: =IF('DASHVOLT REVENUE SCHEDULE'!D45= "Bello Saulawa",'DASHVOLT REVENUE SCHEDULE'!G45, 0) -> 0 | H44: =IF('DASHVOLT REVENUE SCHEDULE'!D45= "Murtala Hassan", 'DASHVOLT REVENUE SCHEDULE'!G45, 0) -> 0 | I44: =IF('DASHVOLT REVENUE SCHEDULE'!D45= "Babangida Monde", 'DASHVOLT REVENUE SCHEDULE'!G45, 0) -> 0 | J44: =IF('DASHVOLT REVENUE SCHEDULE'!D45= "Bello Abdullahi", 'DASHVOLT REVENUE SCHEDULE'!G45, 0) -> 2700
B45: ='DASHVOLT REVENUE SCHEDULE'!B46 -> 45902 | C45: ='DASHVOLT REVENUE SCHEDULE'!C46 -> 0 | D45: ='DASHVOLT REVENUE SCHEDULE'!E46 -> COMPLETED | E45: ='DASHVOLT REVENUE SCHEDULE'!F46 -> CBD | F45: =IF('DASHVOLT REVENUE SCHEDULE'!D46= "Aminu Ibrahim", 'DASHVOLT REVENUE SCHEDULE'!G46, 0) -> 0 | G45: =IF('DASHVOLT REVENUE SCHEDULE'!D46= "Bello Saulawa",'DASHVOLT REVENUE SCHEDULE'!G46, 0) -> 2700 | H45: =IF('DASHVOLT REVENUE SCHEDULE'!D46= "Murtala Hassan", 'DASHVOLT REVENUE SCHEDULE'!G46, 0) -> 0 | I45: =IF('DASHVOLT REVENUE SCHEDULE'!D46= "Babangida Monde", 'DASHVOLT REVENUE SCHEDULE'!G46, 0) -> 0 | J45: =IF('DASHVOLT REVENUE SCHEDULE'!D46= "Bello Abdullahi", 'DASHVOLT REVENUE SCHEDULE'!G46, 0) -> 0
B46: ='DASHVOLT REVENUE SCHEDULE'!B47 -> 45902 | C46: ='DASHVOLT REVENUE SCHEDULE'!C47 -> 0 | D46: ='DASHVOLT REVENUE SCHEDULE'!E47 -> COMPLETED | E46: ='DASHVOLT REVENUE SCHEDULE'!F47 -> Katampe | F46: =IF('DASHVOLT REVENUE SCHEDULE'!D47= "Aminu Ibrahim", 'DASHVOLT REVENUE SCHEDULE'!G47, 0) -> 0 | G46: =IF('DASHVOLT REVENUE SCHEDULE'!D47= "Bello Saulawa",'DASHVOLT REVENUE SCHEDULE'!G47, 0) -> 2500 | H46: =IF('DASHVOLT REVENUE SCHEDULE'!D47= "Murtala Hassan", 'DASHVOLT REVENUE SCHEDULE'!G47, 0) -> 0 | I46: =IF('DASHVOLT REVENUE SCHEDULE'!D47= "Babangida Monde", 'DASHVOLT REVENUE SCHEDULE'!G47, 0) -> 0 | J46: =IF('DASHVOLT REVENUE SCHEDULE'!D47= "Bello Abdullahi", 'DASHVOLT REVENUE SCHEDULE'!G47, 0) -> 0
B47: ='DASHVOLT REVENUE SCHEDULE'!B48 -> 45903 | C47: ='DASHVOLT REVENUE SCHEDULE'!C48 -> 0 | D47: ='DASHVOLT REVENUE SCHEDULE'!E48 -> COMPLETED | E47: ='DASHVOLT REVENUE SCHEDULE'!F48 -> CBD | F47: =IF('DASHVOLT REVENUE SCHEDULE'!D48= "Aminu Ibrahim", 'DASHVOLT REVENUE SCHEDULE'!G48, 0) -> 0 | G47: =IF('DASHVOLT REVENUE SCHEDULE'!D48= "Bello Saulawa",'DASHVOLT REVENUE SCHEDULE'!G48, 0) -> 2700 | H47: =IF('DASHVOLT REVENUE SCHEDULE'!D48= "Murtala Hassan", 'DASHVOLT REVENUE SCHEDULE'!G48, 0) -> 0 | I47: =IF('DASHVOLT REVENUE SCHEDULE'!D48= "Babangida Monde", 'DASHVOLT REVENUE SCHEDULE'!G48, 0) -> 0 | J47: =IF('DASHVOLT REVENUE SCHEDULE'!D48= "Bello Abdullahi", 'DASHVOLT REVENUE SCHEDULE'!G48, 0) -> 0
... B97: ='DASHVOLT REVENUE SCHEDULE'!B98 -> 0 | C97: ='DASHVOLT REVENUE SCHEDULE'!C98 -> 0 | D97: ='DASHVOLT REVENUE SCHEDULE'!E98 -> 0 | E97: ='DASHVOLT REVENUE SCHEDULE'!F98 -> 0 | F97: =IF('DASHVOLT REVENUE SCHEDULE'!D98= "Aminu Ibrahim", 'DASHVOLT REVENUE SCHEDULE'!G98, 0) -> 0 | G97: =IF('DASHVOLT REVENUE SCHEDULE'!D98= "Bello Saulawa",'DASHVOLT REVENUE SCHEDULE'!G98, 0) -> 0 | H97: =IF('DASHVOLT REVENUE SCHEDULE'!D98= "Murtala Hassan", 'DASHVOLT REVENUE SCHEDULE'!G98, 0) -> 0 | I97: =IF('DASHVOLT REVENUE SCHEDULE'!D98= "Babangida Monde", 'DASHVOLT REVENUE SCHEDULE'!G98, 0) -> 0 | J97: =IF('DASHVOLT REVENUE SCHEDULE'!D98= "Bello Abdullahi", 'DASHVOLT REVENUE SCHEDULE'!G98, 0) -> 0
...

Sheet SHARE PER RIDER
B5: Date | C5: Bike Code | D5: Status | E5: Location | F5: Aminu Ibrahim | G5: Bello Saulawa | H5: Murtala Hassan | I5: Babangida Monde | J5: Bello Abdullahi | L5: PERCENTAGE PER RIDER
B6: 45900 | C6: =Table2[[#This Row],[Bike Code]] -> 0 | D6: =Table2[[#This Row],[Status]] -> COMPLETED | E6: =Table2[[#This Row],[Location]] -> JAHI | F6: =Table2[[#This Row],[Aminu Ibrahim]]*$L$6 -> 0 | G6: =Table2[[#This Row],[Bello Saulawa]]*$L$6 -> 870 | H6: =Table2[[#This Row],[Murtala Hassan]]*$L$6 -> 0 | I6: =Table2[[#This Row],[Babangida Monde]]*$L$6 -> 0 | J6: =Table2[[#This Row],[Bello Abdullahi]]*$L$6 -> 0 | L6: 0.3
B7: =Table2[[#This Row],[Date]] -> 45900 | C7: =Table2[[#This Row],[Bike Code]] -> 0 | D7: =Table2[[#This Row],[Status]] -> COMPLETED | E7: =Table2[[#This Row],[Location]] -> Mitama | F7: =Table2[[#This Row],[Aminu Ibrahim]]*$L$6 -> 0 | G7: =Table2[[#This Row],[Bello Saulawa]]*$L$6 -> 750 | H7: =Table2[[#This Row],[Murtala Hassan]]*$L$6 -> 0 | I7: =Table2[[#This Row],[Babangida Monde]]*$L$6 -> 0 | J7: =Table2[[#This Row],[Bello Abdullahi]]*$L$6 -> 0
B8: =Table2[[#This Row],[Date]] -> 45900 | C8: =Table2[[#This Row],[Bike Code]] -> 0 | D8: =Table2[[#This Row],[Status]] -> cOMPLETED | E8: =Table2[[#This Row],[Location]] -> Mitama | F8: =Table2[[#This Row],[Aminu Ibrahim]]*$L$6 -> 0 | G8: =Table2[[#This Row],[Bello Saulawa]]*$L$6 -> 750 | H8: =Table2[[#This Row],[Murtala Hassan]]*$L$6 -> 0 | I8: =Table2[[#This Row],[Babangida Monde]]*$L$6 -> 0 | J8: =Table2[[#This Row],[Bello Abdullahi]]*$L$6 -> 0
B9: =Table2[[#This Row],[Date]] -> 45900 | C9: =Table2[[#This Row],[Bike Code]] -> 0 | D9: =Table2[[#This Row],[Status]] -> COMPLETED | E9: =Table2[[#This Row],[Location]] -> Dawaki | F9: =Table2[[#This Row],[Aminu Ibrahim]]*$L$6 -> 0 | G9: =Table2[[#This Row],[Bello Saulawa]]*$L$6 -> 870 | H9: =Table2[[#This Row],[Murtala Hassan]]*$L$6 -> 0 | I9: =Table2[[#This Row],[Babangida Monde]]*$L$6 -> 0 | J9: =Table2[[#This Row],[Bello Abdullahi]]*$L$6 -> 0
B10: =Table2[[#This Row],[Date]] -> 45900 | C10: =Table2[[#This Row],[Bike Code]] -> 0 | D10: =Table2[[#This Row],[Status]] -> COMPLETED | E10: =Table2[[#This Row],[Location]] -> Jabi | F10: =Table2[[#This Row],[Aminu Ibrahim]]*$L$6 -> 0 | G10: =Table2[[#This Row],[Bello Saulawa]]*$L$6 -> 750 | H10: =Table2[[#This Row],[Murtala Hassan]]*$L$6 -> 0 | I10: =Table2[[#This Row],[Babangida Monde]]*$L$6 -> 0 | J10: =Table2[[#This Row],[Bello Abdullahi]]*$L$6 -> 0
B11: =Table2[[#This Row],[Date]] -> 45900 | C11: =Table2[[#This Row],[Bike Code]] -> 0 | D11: =Table2[[#This Row],[Status]] -> COMPLETED | E11: =Table2[[#This Row],[Location]] -> Dawaki | F11: =Table2[[#This Row],[Aminu Ibrahim]]*$L$6 -> 0 | G11: =Table2[[#This Row],[Bello Saulawa]]*$L$6 -> 870 | H11: =Table2[[#This Row],[Murtala Hassan]]*$L$6 -> 0 | I11: =Table2[[#This Row],[Babangida Monde]]*$L$6 -> 0 | J11: =Table2[[#This Row],[Bello Abdullahi]]*$L$6 -> 0
B12: =Table2[[#This Row],[Date]] -> 45900 | C12: =Table2[[#This Row],[Bike Code]] -> 0 | D12: =Table2[[#This Row],[Status]] -> COMPLETED | E12: =Table2[[#This Row],[Location]] -> Wuse2 | F12: =Table2[[#This Row],[Aminu Ibrahim]]*$L$6 -> 0 | G12: =Table2[[#This Row],[Bello Saulawa]]*$L$6 -> 0 | H12: =Table2[[#This Row],[Murtala Hassan]]*$L$6 -> 750 | I12: =Table2[[#This Row],[Babangida Monde]]*$L$6 -> 0 | J12: =Table2[[#This Row],[Bello Abdullahi]]*$L$6 -> 0
B13: =Table2[[#This Row],[Date]] -> 45900 | C13: =Table2[[#This Row],[Bike Code]] -> 0 | D13: =Table2[[#This Row],[Status]] -> COMPLETED | E13: =Table2[[#This Row],[Location]] -> Utako | F13: =Table2[[#This Row],[Aminu Ibrahim]]*$L$6 -> 0 | G13: =Table2[[#This Row],[Bello Saulawa]]*$L$6 -> 0 | H13: =Table2[[#This Row],[Murtala Hassan]]*$L$6 -> 750 | I13: =Table2[[#This Row],[Babangida Monde]]*$L$6 -> 0 | J13: =Table2[[#This Row],[Bello Abdullahi]]*$L$6 -> 0
B14: =Table2[[#This Row],[Date]] -> 45900 | C14: =Table2[[#This Row],[Bike Code]] -> 0 | D14: =Table2[[#This Row],[Status]] -> COMPLETED | E14: =Table2[[#This Row],[Location]] -> Life camp | F14: =Table2[[#This Row],[Aminu Ibrahim]]*$L$6 -> 0 | G14: =Table2[[#This Row],[Bello Saulawa]]*$L$6 -> 0 | H14: =Table2[[#This Row],[Murtala Hassan]]*$L$6 -> 660 | I14: =Table2[[#This Row],[Babangida Monde]]*$L$6 -> 0 | J14: =Table2[[#This Row],[Bello Abdullahi]]*$L$6 -> 0
B15: =Table2[[#This Row],[Date]] -> 45900 | C15: =Table2[[#This Row],[Bike Code]] -> 0 | D15: =Table2[[#This Row],[Status]] -> COMPLETED | E15: =Table2[[#This Row],[Location]] -> Kado | F15: =Table2[[#This Row],[Aminu Ibrahim]]*$L$6 -> 0 | G15: =Table2[[#This Row],[Bello Saulawa]]*$L$6 -> 0 | H15: =Table2[[#This Row],[Murtala Hassan]]*$L$6 -> 510 | I15: =Table2[[#This Row],[Babangida Monde]]*$L$6 -> 0 | J15: =Table2[[#This Row],[Bello Abdullahi]]*$L$6 -> 0
B16: =Table2[[#This Row],[Date]] -> 45900 | C16: =Table2[[#This Row],[Bike Code]] -> 0 | D16: =Table2[[#This Row],[Status]] -> COMPLETED | E16: =Table2[[#This Row],[Location]] -> Wuse2 | F16: =Table2[[#This Row],[Aminu Ibrahim]]*$L$6 -> 0 | G16: =Table2[[#This Row],[Bello Saulawa]]*$L$6 -> 0 | H16: =Table2[[#This Row],[Murtala Hassan]]*$L$6 -> 0 | I16: =Table2[[#This Row],[Babangida Monde]]*$L$6 -> 0 | J16: =Table2[[#This Row],[Bello Abdullahi]]*$L$6 -> 750
B17: =Table2[[#This Row],[Date]] -> 45900 | C17: =Table2[[#This Row],[Bike Code]] -> 0 | D17: =Table2[[#This Row],[Status]] -> COMPLETED | E17: =Table2[[#This Row],[Location]] -> Kado | F17: =Table2[[#This Row],[Aminu Ibrahim]]*$L$6 -> 0 | G17: =Table2[[#This Row],[Bello Saulawa]]*$L$6 -> 0 | H17: =Table2[[#This Row],[Murtala Hassan]]*$L$6 -> 0 | I17: =Table2[[#This Row],[Babangida Monde]]*$L$6 -> 0 | J17: =Table2[[#This Row],[Bello Abdullahi]]*$L$6 -> 510
B18: =Table2[[#This Row],[Date]] -> 45900 | C18: =Table2[[#This Row],[Bike Code]] -> 0 | D18: =Table2[[#This Row],[Status]] -> COMPLETED | E18: =Table2[[#This Row],[Location]] -> Mitama | F18: =Table2[[#This Row],[Aminu Ibrahim]]*$L$6 -> 0 | G18: =Table2[[#This Row],[Bello Saulawa]]*$L$6 -> 0 | H18: =Table2[[#This Row],[Murtala Hassan]]*$L$6 -> 0 | I18: =Table2[[#This Row],[Babangida Monde]]*$L$6 -> 0 | J18: =Table2[[#This Row],[Bello Abdullahi]]*$L$6 -> 750
... B97: =Table2[[#This Row],[Date]] -> 0 | C97: =Table2[[#This Row],[Bike Code]] -> 0 | D97: =Table2[[#This Row],[Status]] -> 0 | E97: =Table2[[#This Row],[Location]] -> 0 | F97: =Table2[[#This Row],[Aminu Ibrahim]]*$L$6 -> 0 | G97: =Table2[[#This Row],[Bello Saulawa]]*$L$6 -> 0 | H97: =Table2[[#This Row],[Murtala Hassan]]*$L$6 -> 0 | I97: =Table2[[#This Row],[Babangida Monde]]*$L$6 -> 0 | J97: =Table2[[#This Row],[Bello Abdullahi]]*$L$6 -> 0
B98: TOTAL | F98: =SUM(F6:F97) -> 0 | G98: =SUM(G6:G97) -> 33090 | H98: =SUM(H6:H97) -> 14700 | I98: =SUM(I6:I97) -> 0 | J98: =SUM(J6:J97) -> 22050
