Workbook
Name list_totals: YearToDate!$A$9:$Q$34
Name monthNames: {"January";"February";"March";"April";"May";"June";"July";"August";"September";"October";"November";"December"}
Name valuevx: 42.314159

Sheet YearToDate
A1: Employee Leave Tracker | S1: PERAMARE MEDICAL
T2: Employee Leave Tracker
A3: Year: | B3: 2024 | T3: ◄ STEP 1: Update the Year
A5: A = Annual, S = Sick, M = Maternity, CM = Compationate, T = Terminal leave, ST = Study, E = Examination, CA = Casual | T5: ◄ STEP 2a: Define the Types of Leave
A7: Employee | C7: Year Totals
C8: ANNUAL | E8: SICK | G8: MATERNITY | I8: COMPASSIONATE | K8: TERMINAL | M8: STUDY | O8: EXAMINATION | Q8: CASUAL
A9: ID | B9: Name | C9: A | D9: Balance | E9: S | F9: =D9 -> Balance | G9: M | H9: =F9 -> Balance | I9: CM | J9: =H9 -> Balance | K9: T | L9: =J9 -> Balance | M9: ST | N9: =L9 -> Balance | O9: E | P9: =N9 -> Balance | Q9: CA | R9: =P9 -> Balance | S9: Total | T9: ◄ STEP 2b: Update the Labels for the Types of Leave
A10: 1 | B10: AHMAN ABDULJABBAR | C10: =IFERROR(INDEX(Aug!AH$6:AH$31,MATCH($A10,Aug!$A$6:$A$31,0)),0)+IFERROR(INDEX(Sep!AH$6:AH$31,MATCH($A10,Sep!$A$6:$A$31,0)),0)+IFERROR(INDEX(Oct!AH$6:AH$31,MATCH($A10,Oct!$A$6:$A$31,0)),0)+IFERROR(INDEX(Nov!AH$6:AH$31,MATCH($A10,Nov!$A$6:$A$31,0)),0)+IFERROR(INDEX(Dec!AH$6:AH$31,MATCH($A10,Dec!$A$6:$A$31,0)),0)+IFERROR(INDEX(Jan!AH$6:AH$32,MATCH($A10,Jan!$A$6:$A$32,0)),0)+IFERROR(INDEX(Feb!AH$6:AH$28,MATCH($A10,Feb!$A$6:$A$28,0)),0)+IFERROR(INDEX(Mar!AH$6:AH$31,MATCH($A10,Mar!$A$6:$A$31,0)),0)+IFERROR(INDEX(Apr!AH$6:AH$31,MATCH($A10,Apr!$A$6:$A$31,0)),0)+IFERROR(INDEX(May!AH$6:AH$31,MATCH($A10,May!$A$6:$A$31,0)),0)+IFERROR(INDEX(Jun!AH$6:AH$31,MATCH($A10,Jun!$A$6:$A$31,0)),0)+IFERROR(INDEX(Jul!AH$6:AH$31,MATCH($A10,Jul!$A$6:$A$31,0)),0) -> 0 | D10: =IF(C10>0, 21-C10, "") | E10: =IFERROR(INDEX(Aug!AI$6:AI$31,MATCH($A10,Aug!$A$6:$A$31,0)),0)+IFERROR(INDEX(Sep!AI$6:AI$31,MATCH($A10,Sep!$A$6:$A$31,0)),0)+IFERROR(INDEX(Oct!AI$6:AI$31,MATCH($A10,Oct!$A$6:$A$31,0)),0)+IFERROR(INDEX(Nov!AI$6:AI$31,MATCH($A10,Nov!$A$6:$A$31,0)),0)+IFERROR(INDEX(Dec!AI$6:AI$31,MATCH($A10,Dec!$A$6:$A$31,0)),0)+IFERROR(INDEX(Jan!AI$6:AI$32,MATCH($A10,Jan!$A$6:$A$32,0)),0)+IFERROR(INDEX(Feb!AI$6:AI$28,MATCH($A10,Feb!$A$6:$A$28,0)),0)+IFERROR(INDEX(Mar!AI$6:AI$31,MATCH($A10,Mar!$A$6:$A$31,0)),0)+IFERROR(INDEX(Apr!AI$6:AI$31,MATCH($A10,Apr!$A$6:$A$31,0)),0)+IFERROR(INDEX(May!AI$6:AI$31,MATCH($A10,May!$A$6:$A$31,0)),0)+IFERROR(INDEX(Jun!AI$6:AI$31,MATCH($A10,Jun!$A$6:$A$31,0)),0)+IFERROR(INDEX(Jul!AI$6:AI$31,MATCH($A10,Jul!$A$6:$A$31,0)),0) -> 0 | F10: =IF(E10>0, 15-E10, "") | G10: =IFERROR(INDEX(Aug!AJ$6:AJ$31,MATCH($A10,Aug!$A$6:$A$31,0)),0)+IFERROR(INDEX(Sep!AJ$6:AJ$31,MATCH($A10,Sep!$A$6:$A$31,0)),0)+IFERROR(INDEX(Oct!AJ$6:AJ$31,MATCH($A10,Oct!$A$6:$A$31,0)),0)+IFERROR(INDEX(Nov!AJ$6:AJ$31,MATCH($A10,Nov!$A$6:$A$31,0)),0)+IFERROR(INDEX(Dec!AJ$6:AJ$31,MATCH($A10,Dec!$A$6:$A$31,0)),0)+IFERROR(INDEX(Jan!AJ$6:AJ$32,MATCH($A10,Jan!$A$6:$A$32,0)),0)+IFERROR(INDEX(Feb!AJ$6:AJ$28,MATCH($A10,Feb!$A$6:$A$28,0)),0)+IFERROR(INDEX(Mar!AJ$6:AJ$31,MATCH($A10,Mar!$A$6:$A$31,0)),0)+IFERROR(INDEX(Apr!AJ$6:AJ$31,MATCH($A10,Apr!$A$6:$A$31,0)),0)+IFERROR(INDEX(May!AJ$6:AJ$31,MATCH($A10,May!$A$6:$A$31,0)),0)+IFERROR(INDEX(Jun!AJ$6:AJ$31,MATCH($A10,Jun!$A$6:$A$31,0)),0)+IFERROR(INDEX(Jul!AJ$6:AJ$31,MATCH($A10,Jul!$A$6:$A$31,0)),0) -> 0 | H10: =IF(G10>0, 80-G10, "") | I10: =IFERROR(INDEX(Aug!AK$6:AK$31,MATCH($A10,Aug!$A$6:$A$31,0)),0)+IFERROR(INDEX(Sep!AK$6:AK$31,MATCH($A10,Sep!$A$6:$A$31,0)),0)+IFERROR(INDEX(Oct!AK$6:AK$31,MATCH($A10,Oct!$A$6:$A$31,0)),0)+IFERROR(INDEX(Nov!AK$6:AK$31,MATCH($A10,Nov!$A$6:$A$31,0)),0)+IFERROR(INDEX(Dec!AK$6:AK$31,MATCH($A10,Dec!$A$6:$A$31,0)),0)+IFERROR(INDEX(Jan!AK$6:AK$32,MATCH($A10,Jan!$A$6:$A$32,0)),0)+IFERROR(INDEX(Feb!AK$6:AK$28,MATCH($A10,Feb!$A$6:$A$28,0)),0)+IFERROR(INDEX(Mar!AK$6:AK$31,MATCH($A10,Mar!$A$6:$A$31,0)),0)+IFERROR(INDEX(Apr!AK$6:AK$31,MATCH($A10,Apr!$A$6:$A$31,0)),0)+IFERROR(INDEX(May!AK$6:AK$31,MATCH($A10,May!$A$6:$A$31,0)),0)+IFERROR(INDEX(Jun!AK$6:AK$31,MATCH($A10,Jun!$A$6:$A$31,0)),0)+IFERROR(INDEX(Jul!AK$6:AK$31,MATCH($A10,Jul!$A$6:$A$31,0)),0) -> 0 | J10: =IF(I10>0, 5-I10, "") | K10: =IFERROR(INDEX(Aug!AL$6:AL$31,MATCH($A10,Aug!$A$6:$A$31,0)),0)+IFERROR(INDEX(Sep!AL$6:AL$31,MATCH($A10,Sep!$A$6:$A$31,0)),0)+IFERROR(INDEX(Oct!AL$6:AL$31,MATCH($A10,Oct!$A$6:$A$31,0)),0)+IFERROR(INDEX(Nov!AL$6:AL$31,MATCH($A10,Nov!$A$6:$A$31,0)),0)+IFERROR(INDEX(Dec!AL$6:AL$31,MATCH($A10,Dec!$A$6:$A$31,0)),0)+IFERROR(INDEX(Jan!AL$6:AL$32,MATCH($A10,Jan!$A$6:$A$32,0)),0)+IFERROR(INDEX(Feb!AL$6:AL$28,MATCH($A10,Feb!$A$6:$A$28,0)),0)+IFERROR(INDEX(Mar!AL$6:AL$31,MATCH($A10,Mar!$A$6:$A$31,0)),0)+IFERROR(INDEX(Apr!AL$6:AL$31,MATCH($A10,Apr!$A$6:$A$31,0)),0)+IFERROR(INDEX(May!AL$6:AL$31,MATCH($A10,May!$A$6:$A$31,0)),0)+IFERROR(INDEX(Jun!AL$6:AL$31,MATCH($A10,Jun!$A$6:$A$31,0)),0)+IFERROR(INDEX(Jul!AL$6:AL$31,MATCH($A10,Jul!$A$6:$A$31,0)),0) -> 0 | L10: =IF(K10>0, 5-K10, "") | M10: =IFERROR(INDEX(Aug!AM$6:AM$31,MATCH($A10,Aug!$A$6:$A$31,0)),0)+IFERROR(INDEX(Sep!AM$6:AM$31,MATCH($A10,Sep!$A$6:$A$31,0)),0)+IFERROR(INDEX(Oct!AM$6:AM$31,MATCH($A10,Oct!$A$6:$A$31,0)),0)+IFERROR(INDEX(Nov!AM$6:AM$31,MATCH($A10,Nov!$A$6:$A$31,0)),0)+IFERROR(INDEX(Dec!AM$6:AM$31,MATCH($A10,Dec!$A$6:$A$31,0)),0)+IFERROR(INDEX(Jan!AM$6:AM$32,MATCH($A10,Jan!$A$6:$A$32,0)),0)+IFERROR(INDEX(Feb!AM$6:AM$28,MATCH($A10,Feb!$A$6:$A$28,0)),0)+IFERROR(INDEX(Mar!AM$6:AM$31,MATCH($A10,Mar!$A$6:$A$31,0)),0)+IFERROR(INDEX(Apr!AM$6:AM$31,MATCH($A10,Apr!$A$6:$A$31,0)),0)+IFERROR(INDEX(May!AM$6:AM$31,MATCH($A10,May!$A$6:$A$31,0)),0)+IFERROR(INDEX(Jun!AM$6:AM$31,MATCH($A10,Jun!$A$6:$A$31,0)),0)+IFERROR(INDEX(Jul!AM$6:AM$31,MATCH($A10,Jul!$A$6:$A$31,0)),0) -> 0 | N10: =IF(M10>0, 5-M10, "") | O10: =IFERROR(INDEX(Aug!AN$6:AN$31,MATCH($A10,Aug!$A$6:$A$31,0)),0)+IFERROR(INDEX(Sep!AN$6:AN$31,MATCH($A10,Sep!$A$6:$A$31,0)),0)+IFERROR(INDEX(Oct!AN$6:AN$31,MATCH($A10,Oct!$A$6:$A$31,0)),0)+IFERROR(INDEX(Nov!AN$6:AN$31,MATCH($A10,Nov!$A$6:$A$31,0)),0)+IFERROR(INDEX(Dec!AN$6:AN$31,MATCH($A10,Dec!$A$6:$A$31,0)),0)+IFERROR(INDEX(Jan!AN$6:AN$32,MATCH($A10,Jan!$A$6:$A$32,0)),0)+IFERROR(INDEX(Feb!AN$6:AN$28,MATCH($A10,Feb!$A$6:$A$28,0)),0)+IFERROR(INDEX(Mar!AN$6:AN$31,MATCH($A10,Mar!$A$6:$A$31,0)),0)+IFERROR(INDEX(Apr!AN$6:AN$31,MATCH($A10,Apr!$A$6:$A$31,0)),0)+IFERROR(INDEX(May!AN$6:AN$31,MATCH($A10,May!$A$6:$A$31,0)),0)+IFERROR(INDEX(Jun!AN$6:AN$31,MATCH($A10,Jun!$A$6:$A$31,0)),0)+IFERROR(INDEX(Jul!AN$6:AN$31,MATCH($A10,Jul!$A$6:$A$31,0)),0) -> 0 | P10: =IF(O10>0, 5-O10, "") | Q10: =IFERROR(INDEX(Aug!AO$6:AO$31,MATCH($A10,Aug!$A$6:$A$31,0)),0)+IFERROR(INDEX(Sep!AO$6:AO$31,MATCH($A10,Sep!$A$6:$A$31,0)),0)+IFERROR(INDEX(Oct!AO$6:AO$31,MATCH($A10,Oct!$A$6:$A$31,0)),0)+IFERROR(INDEX(Nov!AO$6:AO$31,MATCH($A10,Nov!$A$6:$A$31,0)),0)+IFERROR(INDEX(Dec!AO$6:AO$31,MATCH($A10,Dec!$A$6:$A$31,0)),0)+IFERROR(INDEX(Jan!AO$6:AO$32,MATCH($A10,Jan!$A$6:$A$32,0)),0)+IFERROR(INDEX(Feb!AO$6:AO$28,MATCH($A10,Feb!$A$6:$A$28,0)),0)+IFERROR(INDEX(Mar!AO$6:AO$31,MATCH($A10,Mar!$A$6:$A$31,0)),0)+IFERROR(INDEX(Apr!AO$6:AO$31,MATCH($A10,Apr!$A$6:$A$31,0)),0)+IFERROR(INDEX(May!AO$6:AO$31,MATCH($A10,May!$A$6:$A$31,0)),0)+IFERROR(INDEX(Jun!AO$6:AO$31,MATCH($A10,Jun!$A$6:$A$31,0)),0)+IFERROR(INDEX(Jul!AO$6:AO$31,MATCH($A10,Jul!$A$6:$A$31,0)),0) -> 0 | R10: =IF(Q10>0, 7-Q10, "") | S10: =C10+E10+G10+I10+K10+M10+O10+Q10 -> 0
A11: 2 | B11: ALIYU MUSA ABUBAKAR | C11: =IFERROR(INDEX(Aug!AH$6:AH$31,MATCH($A11,Aug!$A$6:$A$31,0)),0)+IFERROR(INDEX(Sep!AH$6:AH$31,MATCH($A11,Sep!$A$6:$A$31,0)),0)+IFERROR(INDEX(Oct!AH$6:AH$31,MATCH($A11,Oct!$A$6:$A$31,0)),0)+IFERROR(INDEX(Nov!AH$6:AH$31,MATCH($A11,Nov!$A$6:$A$31,0)),0)+IFERROR(INDEX(Dec!AH$6:AH$31,MATCH($A11,Dec!$A$6:$A$31,0)),0)+IFERROR(INDEX(Jan!AH$6:AH$32,MATCH($A11,Jan!$A$6:$A$32,0)),0)+IFERROR(INDEX(Feb!AH$6:AH$28,MATCH($A11,Feb!$A$6:$A$28,0)),0)+IFERROR(INDEX(Mar!AH$6:AH$31,MATCH($A11,Mar!$A$6:$A$31,0)),0)+IFERROR(INDEX(Apr!AH$6:AH$31,MATCH($A11,Apr!$A$6:$A$31,0)),0)+IFERROR(INDEX(May!AH$6:AH$31,MATCH($A11,May!$A$6:$A$31,0)),0)+IFERROR(INDEX(Jun!AH$6:AH$31,MATCH($A11,Jun!$A$6:$A$31,0)),0)+IFERROR(INDEX(Jul!AH$6:AH$31,MATCH($A11,Jul!$A$6:$A$31,0)),0) -> 0 | D11: =IF(C11>0, 21-C11, "") | E11: =IFERROR(INDEX(Aug!AI$6:AI$31,MATCH($A11,Aug!$A$6:$A$31,0)),0)+IFERROR(INDEX(Sep!AI$6:AI$31,MATCH($A11,Sep!$A$6:$A$31,0)),0)+IFERROR(INDEX(Oct!AI$6:AI$31,MATCH($A11,Oct!$A$6:$A$31,0)),0)+IFERROR(INDEX(Nov!AI$6:AI$31,MATCH($A11,Nov!$A$6:$A$31,0)),0)+IFERROR(INDEX(Dec!AI$6:AI$31,MATCH($A11,Dec!$A$6:$A$31,0)),0)+IFERROR(INDEX(Jan!AI$6:AI$32,MATCH($A11,Jan!$A$6:$A$32,0)),0)+IFERROR(INDEX(Feb!AI$6:AI$28,MATCH($A11,Feb!$A$6:$A$28,0)),0)+IFERROR(INDEX(Mar!AI$6:AI$31,MATCH($A11,Mar!$A$6:$A$31,0)),0)+IFERROR(INDEX(Apr!AI$6:AI$31,MATCH($A11,Apr!$A$6:$A$31,0)),0)+IFERROR(INDEX(May!AI$6:AI$31,MATCH($A11,May!$A$6:$A$31,0)),0)+IFERROR(INDEX(Jun!AI$6:AI$31,MATCH($A11,Jun!$A$6:$A$31,0)),0)+IFERROR(INDEX(Jul!AI$6:AI$31,MATCH($A11,Jul!$A$6:$A$31,0)),0) -> 0 | F11: =IF(E11>0, 15-E11, "") | G11: =IFERROR(INDEX(Aug!AJ$6:AJ$31,MATCH($A11,Aug!$A$6:$A$31,0)),0)+IFERROR(INDEX(Sep!AJ$6:AJ$31,MATCH($A11,Sep!$A$6:$A$31,0)),0)+IFERROR(INDEX(Oct!AJ$6:AJ$31,MATCH($A11,Oct!$A$6:$A$31,0)),0)+IFERROR(INDEX(Nov!AJ$6:AJ$31,MATCH($A11,Nov!$A$6:$A$31,0)),0)+IFERROR(INDEX(Dec!AJ$6:AJ$31,MATCH($A11,Dec!$A$6:$A$31,0)),0)+IFERROR(INDEX(Jan!AJ$6:AJ$32,MATCH($A11,Jan!$A$6:$A$32,0)),0)+IFERROR(INDEX(Feb!AJ$6:AJ$28,MATCH($A11,Feb!$A$6:$A$28,0)),0)+IFERROR(INDEX(Mar!AJ$6:AJ$31,MATCH($A11,Mar!$A$6:$A$31,0)),0)+IFERROR(INDEX(Apr!AJ$6:AJ$31,MATCH($A11,Apr!$A$6:$A$31,0)),0)+IFERROR(INDEX(May!AJ$6:AJ$31,MATCH($A11,May!$A$6:$A$31,0)),0)+IFERROR(INDEX(Jun!AJ$6:AJ$31,MATCH($A11,Jun!$A$6:$A$31,0)),0)+IFERROR(INDEX(Jul!AJ$6:AJ$31,MATCH($A11,Jul!$A$6:$A$31,0)),0) -> 0 | H11: =IF(G11>0, 80-G11, "") | I11: =IFERROR(INDEX(Aug!AK$6:AK$31,MATCH($A11,Aug!$A$6:$A$31,0)),0)+IFERROR(INDEX(Sep!AK$6:AK$31,MATCH($A11,Sep!$A$6:$A$31,0)),0)+IFERROR(INDEX(Oct!AK$6:AK$31,MATCH($A11,Oct!$A$6:$A$31,0)),0)+IFERROR(INDEX(Nov!AK$6:AK$31,MATCH($A11,Nov!$A$6:$A$31,0)),0)+IFERROR(INDEX(Dec!AK$6:AK$31,MATCH($A11,Dec!$A$6:$A$31,0)),0)+IFERROR(INDEX(Jan!AK$6:AK$32,MATCH($A11,Jan!$A$6:$A$32,0)),0)+IFERROR(INDEX(Feb!AK$6:AK$28,MATCH($A11,Feb!$A$6:$A$28,0)),0)+IFERROR(INDEX(Mar!AK$6:AK$31,MATCH($A11,Mar!$A$6:$A$31,0)),0)+IFERROR(INDEX(Apr!AK$6:AK$31,MATCH($A11,Apr!$A$6:$A$31,0)),0)+IFERROR(INDEX(May!AK$6:AK$31,MATCH($A11,May!$A$6:$A$31,0)),0)+IFERROR(INDEX(Jun!AK$6:AK$31,MATCH($A11,Jun!$A$6:$A$31,0)),0)+IFERROR(INDEX(Jul!AK$6:AK$31,MATCH($A11,Jul!$A$6:$A$31,0)),0) -> 0 | J11: =IF(I11>0, 5-I11, "") | K11: =IFERROR(INDEX(Aug!AL$6:AL$31,MATCH($A11,Aug!$A$6:$A$31,0)),0)+IFERROR(INDEX(Sep!AL$6:AL$31,MATCH($A11,Sep!$A$6:$A$31,0)),0)+IFERROR(INDEX(Oct!AL$6:AL$31,MATCH($A11,Oct!$A$6:$A$31,0)),0)+IFERROR(INDEX(Nov!AL$6:AL$31,MATCH($A11,Nov!$A$6:$A$31,0)),0)+IFERROR(INDEX(Dec!AL$6:AL$31,MATCH($A11,Dec!$A$6:$A$31,0)),0)+IFERROR(INDEX(Jan!AL$6:AL$32,MATCH($A11,Jan!$A$6:$A$32,0)),0)+IFERROR(INDEX(Feb!AL$6:AL$28,MATCH($A11,Feb!$A$6:$A$28,0)),0)+IFERROR(INDEX(Mar!AL$6:AL$31,MATCH($A11,Mar!$A$6:$A$31,0)),0)+IFERROR(INDEX(Apr!AL$6:AL$31,MATCH($A11,Apr!$A$6:$A$31,0)),0)+IFERROR(INDEX(May!AL$6:AL$31,MATCH($A11,May!$A$6:$A$31,0)),0)+IFERROR(INDEX(Jun!AL$6:AL$31,MATCH($A11,Jun!$A$6:$A$31,0)),0)+IFERROR(INDEX(Jul!AL$6:AL$31,MATCH($A11,Jul!$A$6:$A$31,0)),0) -> 0 | L11: =IF(K11>0, 5-K11, "") | M11: =IFERROR(INDEX(Aug!AM$6:AM$31,MATCH($A11,Aug!$A$6:$A$31,0)),0)+IFERROR(INDEX(Sep!AM$6:AM$31,MATCH($A11,Sep!$A$6:$A$31,0)),0)+IFERROR(INDEX(Oct!AM$6:AM$31,MATCH($A11,Oct!$A$6:$A$31,0)),0)+IFERROR(INDEX(Nov!AM$6:AM$31,MATCH($A11,Nov!$A$6:$A$31,0)),0)+IFERROR(INDEX(Dec!AM$6:AM$31,MATCH($A11,Dec!$A$6:$A$31,0)),0)+IFERROR(INDEX(Jan!AM$6:AM$32,MATCH($A11,Jan!$A$6:$A$32,0)),0)+IFERROR(INDEX(Feb!AM$6:AM$28,MATCH($A11,Feb!$A$6:$A$28,0)),0)+IFERROR(INDEX(Mar!AM$6:AM$31,MATCH($A11,Mar!$A$6:$A$31,0)),0)+IFERROR(INDEX(Apr!AM$6:AM$31,MATCH($A11,Apr!$A$6:$A$31,0)),0)+IFERROR(INDEX(May!AM$6:AM$31,MATCH($A11,May!$A$6:$A$31,0)),0)+IFERROR(INDEX(Jun!AM$6:AM$31,MATCH($A11,Jun!$A$6:$A$31,0)),0)+IFERROR(INDEX(Jul!AM$6:AM$31,MATCH($A11,Jul!$A$6:$A$31,0)),0) -> 0 | N11: =IF(M11>0, 5-M11, "") | O11: =IFERROR(INDEX(Aug!AN$6:AN$31,MATCH($A11,Aug!$A$6:$A$31,0)),0)+IFERROR(INDEX(Sep!AN$6:AN$31,MATCH($A11,Sep!$A$6:$A$31,0)),0)+IFERROR(INDEX(Oct!AN$6:AN$31,MATCH($A11,Oct!$A$6:$A$31,0)),0)+IFERROR(INDEX(Nov!AN$6:AN$31,MATCH($A11,Nov!$A$6:$A$31,0)),0)+IFERROR(INDEX(Dec!AN$6:AN$31,MATCH($A11,Dec!$A$6:$A$31,0)),0)+IFERROR(INDEX(Jan!AN$6:AN$32,MATCH($A11,Jan!$A$6:$A$32,0)),0)+IFERROR(INDEX(Feb!AN$6:AN$28,MATCH($A11,Feb!$A$6:$A$28,0)),0)+IFERROR(INDEX(Mar!AN$6:AN$31,MATCH($A11,Mar!$A$6:$A$31,0)),0)+IFERROR(INDEX(Apr!AN$6:AN$31,MATCH($A11,Apr!$A$6:$A$31,0)),0)+IFERROR(INDEX(May!AN$6:AN$31,MATCH($A11,May!$A$6:$A$31,0)),0)+IFERROR(INDEX(Jun!AN$6:AN$31,MATCH($A11,Jun!$A$6:$A$31,0)),0)+IFERROR(INDEX(Jul!AN$6:AN$31,MATCH($A11,Jul!$A$6:$A$31,0)),0) -> 0 | P11: =IF(O11>0, 5-O11, "") | Q11: =IFERROR(INDEX(Aug!AO$6:AO$31,MATCH($A11,Aug!$A$6:$A$31,0)),0)+IFERROR(INDEX(Sep!AO$6:AO$31,MATCH($A11,Sep!$A$6:$A$31,0)),0)+IFERROR(INDEX(Oct!AO$6:AO$31,MATCH($A11,Oct!$A$6:$A$31,0)),0)+IFERROR(INDEX(Nov!AO$6:AO$31,MATCH($A11,Nov!$A$6:$A$31,0)),0)+IFERROR(INDEX(Dec!AO$6:AO$31,MATCH($A11,Dec!$A$6:$A$31,0)),0)+IFERROR(INDEX(Jan!AO$6:AO$32,MATCH($A11,Jan!$A$6:$A$32,0)),0)+IFERROR(INDEX(Feb!AO$6:AO$28,MATCH($A11,Feb!$A$6:$A$28,0)),0)+IFERROR(INDEX(Mar!AO$6:AO$31,MATCH($A11,Mar!$A$6:$A$31,0)),0)+IFERROR(INDEX(Apr!AO$6:AO$31,MATCH($A11,Apr!$A$6:$A$31,0)),0)+IFERROR(INDEX(May!AO$6:AO$31,MATCH($A11,May!$A$6:$A$31,0)),0)+IFERROR(INDEX(Jun!AO$6:AO$31,MATCH($A11,Jun!$A$6:$A$31,0)),0)+IFERROR(INDEX(Jul!AO$6:AO$31,MATCH($A11,Jul!$A$6:$A$31,0)),0) -> 0 | R11: =IF(Q11>0, 7-Q11, "") | S11: =C11+E11+G11+I11+K11+M11+O11+Q11 -> 0 | T11: ◄ STEP 3: Edit the list of Employees
A12: 3 | B12: GOSTA ALIYU | C12: =IFERROR(INDEX(Aug!AH$6:AH$31,MATCH($A12,Aug!$A$6:$A$31,0)),0)+IFERROR(INDEX(Sep!AH$6:AH$31,MATCH($A12,Sep!$A$6:$A$31,0)),0)+IFERROR(INDEX(Oct!AH$6:AH$31,MATCH($A12,Oct!$A$6:$A$31,0)),0)+IFERROR(INDEX(Nov!AH$6:AH$31,MATCH($A12,Nov!$A$6:$A$31,0)),0)+IFERROR(INDEX(Dec!AH$6:AH$31,MATCH($A12,Dec!$A$6:$A$31,0)),0)+IFERROR(INDEX(Jan!AH$6:AH$32,MATCH($A12,Jan!$A$6:$A$32,0)),0)+IFERROR(INDEX(Feb!AH$6:AH$28,MATCH($A12,Feb!$A$6:$A$28,0)),0)+IFERROR(INDEX(Mar!AH$6:AH$31,MATCH($A12,Mar!$A$6:$A$31,0)),0)+IFERROR(INDEX(Apr!AH$6:AH$31,MATCH($A12,Apr!$A$6:$A$31,0)),0)+IFERROR(INDEX(May!AH$6:AH$31,MATCH($A12,May!$A$6:$A$31,0)),0)+IFERROR(INDEX(Jun!AH$6:AH$31,MATCH($A12,Jun!$A$6:$A$31,0)),0)+IFERROR(INDEX(Jul!AH$6:AH$31,MATCH($A12,Jul!$A$6:$A$31,0)),0) -> 0 | D12: =IF(C12>0, 21-C12, "") | E12: =IFERROR(INDEX(Aug!AI$6:AI$31,MATCH($A12,Aug!$A$6:$A$31,0)),0)+IFERROR(INDEX(Sep!AI$6:AI$31,MATCH($A12,Sep!$A$6:$A$31,0)),0)+IFERROR(INDEX(Oct!AI$6:AI$31,MATCH($A12,Oct!$A$6:$A$31,0)),0)+IFERROR(INDEX(Nov!AI$6:AI$31,MATCH($A12,Nov!$A$6:$A$31,0)),0)+IFERROR(INDEX(Dec!AI$6:AI$31,MATCH($A12,Dec!$A$6:$A$31,0)),0)+IFERROR(INDEX(Jan!AI$6:AI$32,MATCH($A12,Jan!$A$6:$A$32,0)),0)+IFERROR(INDEX(Feb!AI$6:AI$28,MATCH($A12,Feb!$A$6:$A$28,0)),0)+IFERROR(INDEX(Mar!AI$6:AI$31,MATCH($A12,Mar!$A$6:$A$31,0)),0)+IFERROR(INDEX(Apr!AI$6:AI$31,MATCH($A12,Apr!$A$6:$A$31,0)),0)+IFERROR(INDEX(May!AI$6:AI$31,MATCH($A12,May!$A$6:$A$31,0)),0)+IFERROR(INDEX(Jun!AI$6:AI$31,MATCH($A12,Jun!$A$6:$A$31,0)),0)+IFERROR(INDEX(Jul!AI$6:AI$31,MATCH($A12,Jul!$A$6:$A$31,0)),0) -> 0 | F12: =IF(E12>0, 15-E12, "") | G12: =IFERROR(INDEX(Aug!AJ$6:AJ$31,MATCH($A12,Aug!$A$6:$A$31,0)),0)+IFERROR(INDEX(Sep!AJ$6:AJ$31,MATCH($A12,Sep!$A$6:$A$31,0)),0)+IFERROR(INDEX(Oct!AJ$6:AJ$31,MATCH($A12,Oct!$A$6:$A$31,0)),0)+IFERROR(INDEX(Nov!AJ$6:AJ$31,MATCH($A12,Nov!$A$6:$A$31,0)),0)+IFERROR(INDEX(Dec!AJ$6:AJ$31,MATCH($A12,Dec!$A$6:$A$31,0)),0)+IFERROR(INDEX(Jan!AJ$6:AJ$32,MATCH($A12,Jan!$A$6:$A$32,0)),0)+IFERROR(INDEX(Feb!AJ$6:AJ$28,MATCH($A12,Feb!$A$6:$A$28,0)),0)+IFERROR(INDEX(Mar!AJ$6:AJ$31,MATCH($A12,Mar!$A$6:$A$31,0)),0)+IFERROR(INDEX(Apr!AJ$6:AJ$31,MATCH($A12,Apr!$A$6:$A$31,0)),0)+IFERROR(INDEX(May!AJ$6:AJ$31,MATCH($A12,May!$A$6:$A$31,0)),0)+IFERROR(INDEX(Jun!AJ$6:AJ$31,MATCH($A12,Jun!$A$6:$A$31,0)),0)+IFERROR(INDEX(Jul!AJ$6:AJ$31,MATCH($A12,Jul!$A$6:$A$31,0)),0) -> 0 | H12: =IF(G12>0, 80-G12, "") | I12: =IFERROR(INDEX(Aug!AK$6:AK$31,MATCH($A12,Aug!$A$6:$A$31,0)),0)+IFERROR(INDEX(Sep!AK$6:AK$31,MATCH($A12,Sep!$A$6:$A$31,0)),0)+IFERROR(INDEX(Oct!AK$6:AK$31,MATCH($A12,Oct!$A$6:$A$31,0)),0)+IFERROR(INDEX(Nov!AK$6:AK$31,MATCH($A12,Nov!$A$6:$A$31,0)),0)+IFERROR(INDEX(Dec!AK$6:AK$31,MATCH($A12,Dec!$A$6:$A$31,0)),0)+IFERROR(INDEX(Jan!AK$6:AK$32,MATCH($A12,Jan!$A$6:$A$32,0)),0)+IFERROR(INDEX(Feb!AK$6:AK$28,MATCH($A12,Feb!$A$6:$A$28,0)),0)+IFERROR(INDEX(Mar!AK$6:AK$31,MATCH($A12,Mar!$A$6:$A$31,0)),0)+IFERROR(INDEX(Apr!AK$6:AK$31,MATCH($A12,Apr!$A$6:$A$31,0)),0)+IFERROR(INDEX(May!AK$6:AK$31,MATCH($A12,May!$A$6:$A$31,0)),0)+IFERROR(INDEX(Jun!AK$6:AK$31,MATCH($A12,Jun!$A$6:$A$31,0)),0)+IFERROR(INDEX(Jul!AK$6:AK$31,MATCH($A12,Jul!$A$6:$A$31,0)),0) -> 0 | J12: =IF(I12>0, 5-I12, "") | K12: =IFERROR(INDEX(Aug!AL$6:AL$31,MATCH($A12,Aug!$A$6:$A$31,0)),0)+IFERROR(INDEX(Sep!AL$6:AL$31,MATCH($A12,Sep!$A$6:$A$31,0)),0)+IFERROR(INDEX(Oct!AL$6:AL$31,MATCH($A12,Oct!$A$6:$A$31,0)),0)+IFERROR(INDEX(Nov!AL$6:AL$31,MATCH($A12,Nov!$A$6:$A$31,0)),0)+IFERROR(INDEX(Dec!AL$6:AL$31,MATCH($A12,Dec!$A$6:$A$31,0)),0)+IFERROR(INDEX(Jan!AL$6:AL$32,MATCH($A12,Jan!$A$6:$A$32,0)),0)+IFERROR(INDEX(Feb!AL$6:AL$28,MATCH($A12,Feb!$A$6:$A$28,0)),0)+IFERROR(INDEX(Mar!AL$6:AL$31,MATCH($A12,Mar!$A$6:$A$31,0)),0)+IFERROR(INDEX(Apr!AL$6:AL$31,MATCH($A12,Apr!$A$6:$A$31,0)),0)+IFERROR(INDEX(May!AL$6:AL$31,MATCH($A12,May!$A$6:$A$31,0)),0)+IFERROR(INDEX(Jun!AL$6:AL$31,MATCH($A12,Jun!$A$6:$A$31,0)),0)+IFERROR(INDEX(Jul!AL$6:AL$31,MATCH($A12,Jul!$A$6:$A$31,0)),0) -> 0 | L12: =IF(K12>0, 5-K12, "") | M12: =IFERROR(INDEX(Aug!AM$6:AM$31,MATCH($A12,Aug!$A$6:$A$31,0)),0)+IFERROR(INDEX(Sep!AM$6:AM$31,MATCH($A12,Sep!$A$6:$A$31,0)),0)+IFERROR(INDEX(Oct!AM$6:AM$31,MATCH($A12,Oct!$A$6:$A$31,0)),0)+IFERROR(INDEX(Nov!AM$6:AM$31,MATCH($A12,Nov!$A$6:$A$31,0)),0)+IFERROR(INDEX(Dec!AM$6:AM$31,MATCH($A12,Dec!$A$6:$A$31,0)),0)+IFERROR(INDEX(Jan!AM$6:AM$32,MATCH($A12,Jan!$A$6:$A$32,0)),0)+IFERROR(INDEX(Feb!AM$6:AM$28,MATCH($A12,Feb!$A$6:$A$28,0)),0)+IFERROR(INDEX(Mar!AM$6:AM$31,MATCH($A12,Mar!$A$6:$A$31,0)),0)+IFERROR(INDEX(Apr!AM$6:AM$31,MATCH($A12,Apr!$A$6:$A$31,0)),0)+IFERROR(INDEX(May!AM$6:AM$31,MATCH($A12,May!$A$6:$A$31,0)),0)+IFERROR(INDEX(Jun!AM$6:AM$31,MATCH($A12,Jun!$A$6:$A$31,0)),0)+IFERROR(INDEX(Jul!AM$6:AM$31,MATCH($A12,Jul!$A$6:$A$31,0)),0) -> 0 | N12: =IF(M12>0, 5-M12, "") | O12: =IFERROR(INDEX(Aug!AN$6:AN$31,MATCH($A12,Aug!$A$6:$A$31,0)),0)+IFERROR(INDEX(Sep!AN$6:AN$31,MATCH($A12,Sep!$A$6:$A$31,0)),0)+IFERROR(INDEX(Oct!AN$6:AN$31,MATCH($A12,Oct!$A$6:$A$31,0)),0)+IFERROR(INDEX(Nov!AN$6:AN$31,MATCH($A12,Nov!$A$6:$A$31,0)),0)+IFERROR(INDEX(Dec!AN$6:AN$31,MATCH($A12,Dec!$A$6:$A$31,0)),0)+IFERROR(INDEX(Jan!AN$6:AN$32,MATCH($A12,Jan!$A$6:$A$32,0)),0)+IFERROR(INDEX(Feb!AN$6:AN$28,MATCH($A12,Feb!$A$6:$A$28,0)),0)+IFERROR(INDEX(Mar!AN$6:AN$31,MATCH($A12,Mar!$A$6:$A$31,0)),0)+IFERROR(INDEX(Apr!AN$6:AN$31,MATCH($A12,Apr!$A$6:$A$31,0)),0)+IFERROR(INDEX(May!AN$6:AN$31,MATCH($A12,May!$A$6:$A$31,0)),0)+IFERROR(INDEX(Jun!AN$6:AN$31,MATCH($A12,Jun!$A$6:$A$31,0)),0)+IFERROR(INDEX(Jul!AN$6:AN$31,MATCH($A12,Jul!$A$6:$A$31,0)),0) -> 0 | P12: =IF(O12>0, 5-O12, "") | Q12: =IFERROR(INDEX(Aug!AO$6:AO$31,MATCH($A12,Aug!$A$6:$A$31,0)),0)+IFERROR(INDEX(Sep!AO$6:AO$31,MATCH($A12,Sep!$A$6:$A$31,0)),0)+IFERROR(INDEX(Oct!AO$6:AO$31,MATCH($A12,Oct!$A$6:$A$31,0)),0)+IFERROR(INDEX(Nov!AO$6:AO$31,MATCH($A12,Nov!$A$6:$A$31,0)),0)+IFERROR(INDEX(Dec!AO$6:AO$31,MATCH($A12,Dec!$A$6:$A$31,0)),0)+IFERROR(INDEX(Jan!AO$6:AO$32,MATCH($A12,Jan!$A$6:$A$32,0)),0)+IFERROR(INDEX(Feb!AO$6:AO$28,MATCH($A12,Feb!$A$6:$A$28,0)),0)+IFERROR(INDEX(Mar!AO$6:AO$31,MATCH($A12,Mar!$A$6:$A$31,0)),0)+IFERROR(INDEX(Apr!AO$6:AO$31,MATCH($A12,Apr!$A$6:$A$31,0)),0)+IFERROR(INDEX(May!AO$6:AO$31,MATCH($A12,May!$A$6:$A$31,0)),0)+IFERROR(INDEX(Jun!AO$6:AO$31,MATCH($A12,Jun!$A$6:$A$31,0)),0)+IFERROR(INDEX(Jul!AO$6:AO$31,MATCH($A12,Jul!$A$6:$A$31,0)),0) -> 0 | R12: =IF(Q12>0, 7-Q12, "") | S12: =C12+E12+G12+I12+K12+M12+O12+Q12 -> 0
A13: 4 | B13: IBRAHIM TUKURA RILWAN | C13: =IFERROR(INDEX(Aug!AH$6:AH$31,MATCH($A13,Aug!$A$6:$A$31,0)),0)+IFERROR(INDEX(Sep!AH$6:AH$31,MATCH($A13,Sep!$A$6:$A$31,0)),0)+IFERROR(INDEX(Oct!AH$6:AH$31,MATCH($A13,Oct!$A$6:$A$31,0)),0)+IFERROR(INDEX(Nov!AH$6:AH$31,MATCH($A13,Nov!$A$6:$A$31,0)),0)+IFERROR(INDEX(Dec!AH$6:AH$31,MATCH($A13,Dec!$A$6:$A$31,0)),0)+IFERROR(INDEX(Jan!AH$6:AH$32,MATCH($A13,Jan!$A$6:$A$32,0)),0)+IFERROR(INDEX(Feb!AH$6:AH$28,MATCH($A13,Feb!$A$6:$A$28,0)),0)+IFERROR(INDEX(Mar!AH$6:AH$31,MATCH($A13,Mar!$A$6:$A$31,0)),0)+IFERROR(INDEX(Apr!AH$6:AH$31,MATCH($A13,Apr!$A$6:$A$31,0)),0)+IFERROR(INDEX(May!AH$6:AH$31,MATCH($A13,May!$A$6:$A$31,0)),0)+IFERROR(INDEX(Jun!AH$6:AH$31,MATCH($A13,Jun!$A$6:$A$31,0)),0)+IFERROR(INDEX(Jul!AH$6:AH$31,MATCH($A13,Jul!$A$6:$A$31,0)),0) -> 0 | D13: =IF(C13>0, 13-C13, "") | E13: =IFERROR(INDEX(Aug!AI$6:AI$31,MATCH($A13,Aug!$A$6:$A$31,0)),0)+IFERROR(INDEX(Sep!AI$6:AI$31,MATCH($A13,Sep!$A$6:$A$31,0)),0)+IFERROR(INDEX(Oct!AI$6:AI$31,MATCH($A13,Oct!$A$6:$A$31,0)),0)+IFERROR(INDEX(Nov!AI$6:AI$31,MATCH($A13,Nov!$A$6:$A$31,0)),0)+IFERROR(INDEX(Dec!AI$6:AI$31,MATCH($A13,Dec!$A$6:$A$31,0)),0)+IFERROR(INDEX(Jan!AI$6:AI$32,MATCH($A13,Jan!$A$6:$A$32,0)),0)+IFERROR(INDEX(Feb!AI$6:AI$28,MATCH($A13,Feb!$A$6:$A$28,0)),0)+IFERROR(INDEX(Mar!AI$6:AI$31,MATCH($A13,Mar!$A$6:$A$31,0)),0)+IFERROR(INDEX(Apr!AI$6:AI$31,MATCH($A13,Apr!$A$6:$A$31,0)),0)+IFERROR(INDEX(May!AI$6:AI$31,MATCH($A13,May!$A$6:$A$31,0)),0)+IFERROR(INDEX(Jun!AI$6:AI$31,MATCH($A13,Jun!$A$6:$A$31,0)),0)+IFERROR(INDEX(Jul!AI$6:AI$31,MATCH($A13,Jul!$A$6:$A$31,0)),0) -> 0 | F13: =IF(E13>0, 9-E13, "") | G13: =IFERROR(INDEX(Aug!AJ$6:AJ$31,MATCH($A13,Aug!$A$6:$A$31,0)),0)+IFERROR(INDEX(Sep!AJ$6:AJ$31,MATCH($A13,Sep!$A$6:$A$31,0)),0)+IFERROR(INDEX(Oct!AJ$6:AJ$31,MATCH($A13,Oct!$A$6:$A$31,0)),0)+IFERROR(INDEX(Nov!AJ$6:AJ$31,MATCH($A13,Nov!$A$6:$A$31,0)),0)+IFERROR(INDEX(Dec!AJ$6:AJ$31,MATCH($A13,Dec!$A$6:$A$31,0)),0)+IFERROR(INDEX(Jan!AJ$6:AJ$32,MATCH($A13,Jan!$A$6:$A$32,0)),0)+IFERROR(INDEX(Feb!AJ$6:AJ$28,MATCH($A13,Feb!$A$6:$A$28,0)),0)+IFERROR(INDEX(Mar!AJ$6:AJ$31,MATCH($A13,Mar!$A$6:$A$31,0)),0)+IFERROR(INDEX(Apr!AJ$6:AJ$31,MATCH($A13,Apr!$A$6:$A$31,0)),0)+IFERROR(INDEX(May!AJ$6:AJ$31,MATCH($A13,May!$A$6:$A$31,0)),0)+IFERROR(INDEX(Jun!AJ$6:AJ$31,MATCH($A13,Jun!$A$6:$A$31,0)),0)+IFERROR(INDEX(Jul!AJ$6:AJ$31,MATCH($A13,Jul!$A$6:$A$31,0)),0) -> 0 | H13: =IF(G13>0, 50-G13, "") | I13: =IFERROR(INDEX(Aug!AK$6:AK$31,MATCH($A13,Aug!$A$6:$A$31,0)),0)+IFERROR(INDEX(Sep!AK$6:AK$31,MATCH($A13,Sep!$A$6:$A$31,0)),0)+IFERROR(INDEX(Oct!AK$6:AK$31,MATCH($A13,Oct!$A$6:$A$31,0)),0)+IFERROR(INDEX(Nov!AK$6:AK$31,MATCH($A13,Nov!$A$6:$A$31,0)),0)+IFERROR(INDEX(Dec!AK$6:AK$31,MATCH($A13,Dec!$A$6:$A$31,0)),0)+IFERROR(INDEX(Jan!AK$6:AK$32,MATCH($A13,Jan!$A$6:$A$32,0)),0)+IFERROR(INDEX(Feb!AK$6:AK$28,MATCH($A13,Feb!$A$6:$A$28,0)),0)+IFERROR(INDEX(Mar!AK$6:AK$31,MATCH($A13,Mar!$A$6:$A$31,0)),0)+IFERROR(INDEX(Apr!AK$6:AK$31,MATCH($A13,Apr!$A$6:$A$31,0)),0)+IFERROR(INDEX(May!AK$6:AK$31,MATCH($A13,May!$A$6:$A$31,0)),0)+IFERROR(INDEX(Jun!AK$6:AK$31,MATCH($A13,Jun!$A$6:$A$31,0)),0)+IFERROR(INDEX(Jul!AK$6:AK$31,MATCH($A13,Jul!$A$6:$A$31,0)),0) -> 0 | J13: =IF(I13>0, 5-I13, "") | K13: =IFERROR(INDEX(Aug!AL$6:AL$31,MATCH($A13,Aug!$A$6:$A$31,0)),0)+IFERROR(INDEX(Sep!AL$6:AL$31,MATCH($A13,Sep!$A$6:$A$31,0)),0)+IFERROR(INDEX(Oct!AL$6:AL$31,MATCH($A13,Oct!$A$6:$A$31,0)),0)+IFERROR(INDEX(Nov!AL$6:AL$31,MATCH($A13,Nov!$A$6:$A$31,0)),0)+IFERROR(INDEX(Dec!AL$6:AL$31,MATCH($A13,Dec!$A$6:$A$31,0)),0)+IFERROR(INDEX(Jan!AL$6:AL$32,MATCH($A13,Jan!$A$6:$A$32,0)),0)+IFERROR(INDEX(Feb!AL$6:AL$28,MATCH($A13,Feb!$A$6:$A$28,0)),0)+IFERROR(INDEX(Mar!AL$6:AL$31,MATCH($A13,Mar!$A$6:$A$31,0)),0)+IFERROR(INDEX(Apr!AL$6:AL$31,MATCH($A13,Apr!$A$6:$A$31,0)),0)+IFERROR(INDEX(May!AL$6:AL$31,MATCH($A13,May!$A$6:$A$31,0)),0)+IFERROR(INDEX(Jun!AL$6:AL$31,MATCH($A13,Jun!$A$6:$A$31,0)),0)+IFERROR(INDEX(Jul!AL$6:AL$31,MATCH($A13,Jul!$A$6:$A$31,0)),0) -> 0 | L13: =IF(K13>0, 5-K13, "") | M13: =IFERROR(INDEX(Aug!AM$6:AM$31,MATCH($A13,Aug!$A$6:$A$31,0)),0)+IFERROR(INDEX(Sep!AM$6:AM$31,MATCH($A13,Sep!$A$6:$A$31,0)),0)+IFERROR(INDEX(Oct!AM$6:AM$31,MATCH($A13,Oct!$A$6:$A$31,0)),0)+IFERROR(INDEX(Nov!AM$6:AM$31,MATCH($A13,Nov!$A$6:$A$31,0)),0)+IFERROR(INDEX(Dec!AM$6:AM$31,MATCH($A13,Dec!$A$6:$A$31,0)),0)+IFERROR(INDEX(Jan!AM$6:AM$32,MATCH($A13,Jan!$A$6:$A$32,0)),0)+IFERROR(INDEX(Feb!AM$6:AM$28,MATCH($A13,Feb!$A$6:$A$28,0)),0)+IFERROR(INDEX(Mar!AM$6:AM$31,MATCH($A13,Mar!$A$6:$A$31,0)),0)+IFERROR(INDEX(Apr!AM$6:AM$31,MATCH($A13,Apr!$A$6:$A$31,0)),0)+IFERROR(INDEX(May!AM$6:AM$31,MATCH($A13,May!$A$6:$A$31,0)),0)+IFERROR(INDEX(Jun!AM$6:AM$31,MATCH($A13,Jun!$A$6:$A$31,0)),0)+IFERROR(INDEX(Jul!AM$6:AM$31,MATCH($A13,Jul!$A$6:$A$31,0)),0) -> 0 | N13: =IF(M13>0, 5-M13, "") | O13: =IFERROR(INDEX(Aug!AN$6:AN$31,MATCH($A13,Aug!$A$6:$A$31,0)),0)+IFERROR(INDEX(Sep!AN$6:AN$31,MATCH($A13,Sep!$A$6:$A$31,0)),0)+IFERROR(INDEX(Oct!AN$6:AN$31,MATCH($A13,Oct!$A$6:$A$31,0)),0)+IFERROR(INDEX(Nov!AN$6:AN$31,MATCH($A13,Nov!$A$6:$A$31,0)),0)+IFERROR(INDEX(Dec!AN$6:AN$31,MATCH($A13,Dec!$A$6:$A$31,0)),0)+IFERROR(INDEX(Jan!AN$6:AN$32,MATCH($A13,Jan!$A$6:$A$32,0)),0)+IFERROR(INDEX(Feb!AN$6:AN$28,MATCH($A13,Feb!$A$6:$A$28,0)),0)+IFERROR(INDEX(Mar!AN$6:AN$31,MATCH($A13,Mar!$A$6:$A$31,0)),0)+IFERROR(INDEX(Apr!AN$6:AN$31,MATCH($A13,Apr!$A$6:$A$31,0)),0)+IFERROR(INDEX(May!AN$6:AN$31,MATCH($A13,May!$A$6:$A$31,0)),0)+IFERROR(INDEX(Jun!AN$6:AN$31,MATCH($A13,Jun!$A$6:$A$31,0)),0)+IFERROR(INDEX(Jul!AN$6:AN$31,MATCH($A13,Jul!$A$6:$A$31,0)),0) -> 0 | P13: =IF(O13>0, 5-O13, "") | Q13: =IFERROR(INDEX(Aug!AO$6:AO$31,MATCH($A13,Aug!$A$6:$A$31,0)),0)+IFERROR(INDEX(Sep!AO$6:AO$31,MATCH($A13,Sep!$A$6:$A$31,0)),0)+IFERROR(INDEX(Oct!AO$6:AO$31,MATCH($A13,Oct!$A$6:$A$31,0)),0)+IFERROR(INDEX(Nov!AO$6:AO$31,MATCH($A13,Nov!$A$6:$A$31,0)),0)+IFERROR(INDEX(Dec!AO$6:AO$31,MATCH($A13,Dec!$A$6:$A$31,0)),0)+IFERROR(INDEX(Jan!AO$6:AO$32,MATCH($A13,Jan!$A$6:$A$32,0)),0)+IFERROR(INDEX(Feb!AO$6:AO$28,MATCH($A13,Feb!$A$6:$A$28,0)),0)+IFERROR(INDEX(Mar!AO$6:AO$31,MATCH($A13,Mar!$A$6:$A$31,0)),0)+IFERROR(INDEX(Apr!AO$6:AO$31,MATCH($A13,Apr!$A$6:$A$31,0)),0)+IFERROR(INDEX(May!AO$6:AO$31,MATCH($A13,May!$A$6:$A$31,0)),0)+IFERROR(INDEX(Jun!AO$6:AO$31,MATCH($A13,Jun!$A$6:$A$31,0)),0)+IFERROR(INDEX(Jul!AO$6:AO$31,MATCH($A13,Jul!$A$6:$A$31,0)),0) -> 0 | R13: =IF(Q13>0, 4-Q13, "") | S13: =C13+E13+G13+I13+K13+M13+O13+Q13 -> 0 | T13: STEP 4: Use Monthly worksheets to Enter Leave
A14: 5 | B14: HASSAN HABEEB | C14: =IFERROR(INDEX(Aug!AH$6:AH$31,MATCH($A14,Aug!$A$6:$A$31,0)),0)+IFERROR(INDEX(Sep!AH$6:AH$31,MATCH($A14,Sep!$A$6:$A$31,0)),0)+IFERROR(INDEX(Oct!AH$6:AH$31,MATCH($A14,Oct!$A$6:$A$31,0)),0)+IFERROR(INDEX(Nov!AH$6:AH$31,MATCH($A14,Nov!$A$6:$A$31,0)),0)+IFERROR(INDEX(Dec!AH$6:AH$31,MATCH($A14,Dec!$A$6:$A$31,0)),0)+IFERROR(INDEX(Jan!AH$6:AH$32,MATCH($A14,Jan!$A$6:$A$32,0)),0)+IFERROR(INDEX(Feb!AH$6:AH$28,MATCH($A14,Feb!$A$6:$A$28,0)),0)+IFERROR(INDEX(Mar!AH$6:AH$31,MATCH($A14,Mar!$A$6:$A$31,0)),0)+IFERROR(INDEX(Apr!AH$6:AH$31,MATCH($A14,Apr!$A$6:$A$31,0)),0)+IFERROR(INDEX(May!AH$6:AH$31,MATCH($A14,May!$A$6:$A$31,0)),0)+IFERROR(INDEX(Jun!AH$6:AH$31,MATCH($A14,Jun!$A$6:$A$31,0)),0)+IFERROR(INDEX(Jul!AH$6:AH$31,MATCH($A14,Jul!$A$6:$A$31,0)),0) -> 0 | D14: =IF(C14>0, 21-C14, "") | E14: =IFERROR(INDEX(Aug!AI$6:AI$31,MATCH($A14,Aug!$A$6:$A$31,0)),0)+IFERROR(INDEX(Sep!AI$6:AI$31,MATCH($A14,Sep!$A$6:$A$31,0)),0)+IFERROR(INDEX(Oct!AI$6:AI$31,MATCH($A14,Oct!$A$6:$A$31,0)),0)+IFERROR(INDEX(Nov!AI$6:AI$31,MATCH($A14,Nov!$A$6:$A$31,0)),0)+IFERROR(INDEX(Dec!AI$6:AI$31,MATCH($A14,Dec!$A$6:$A$31,0)),0)+IFERROR(INDEX(Jan!AI$6:AI$32,MATCH($A14,Jan!$A$6:$A$32,0)),0)+IFERROR(INDEX(Feb!AI$6:AI$28,MATCH($A14,Feb!$A$6:$A$28,0)),0)+IFERROR(INDEX(Mar!AI$6:AI$31,MATCH($A14,Mar!$A$6:$A$31,0)),0)+IFERROR(INDEX(Apr!AI$6:AI$31,MATCH($A14,Apr!$A$6:$A$31,0)),0)+IFERROR(INDEX(May!AI$6:AI$31,MATCH($A14,May!$A$6:$A$31,0)),0)+IFERROR(INDEX(Jun!AI$6:AI$31,MATCH($A14,Jun!$A$6:$A$31,0)),0)+IFERROR(INDEX(Jul!AI$6:AI$31,MATCH($A14,Jul!$A$6:$A$31,0)),0) -> 0 | F14: =IF(E14>0, 15-E14, "") | G14: =IFERROR(INDEX(Aug!AJ$6:AJ$31,MATCH($A14,Aug!$A$6:$A$31,0)),0)+IFERROR(INDEX(Sep!AJ$6:AJ$31,MATCH($A14,Sep!$A$6:$A$31,0)),0)+IFERROR(INDEX(Oct!AJ$6:AJ$31,MATCH($A14,Oct!$A$6:$A$31,0)),0)+IFERROR(INDEX(Nov!AJ$6:AJ$31,MATCH($A14,Nov!$A$6:$A$31,0)),0)+IFERROR(INDEX(Dec!AJ$6:AJ$31,MATCH($A14,Dec!$A$6:$A$31,0)),0)+IFERROR(INDEX(Jan!AJ$6:AJ$32,MATCH($A14,Jan!$A$6:$A$32,0)),0)+IFERROR(INDEX(Feb!AJ$6:AJ$28,MATCH($A14,Feb!$A$6:$A$28,0)),0)+IFERROR(INDEX(Mar!AJ$6:AJ$31,MATCH($A14,Mar!$A$6:$A$31,0)),0)+IFERROR(INDEX(Apr!AJ$6:AJ$31,MATCH($A14,Apr!$A$6:$A$31,0)),0)+IFERROR(INDEX(May!AJ$6:AJ$31,MATCH($A14,May!$A$6:$A$31,0)),0)+IFERROR(INDEX(Jun!AJ$6:AJ$31,MATCH($A14,Jun!$A$6:$A$31,0)),0)+IFERROR(INDEX(Jul!AJ$6:AJ$31,MATCH($A14,Jul!$A$6:$A$31,0)),0) -> 0 | H14: =IF(G14>0, 80-G14, "") | I14: =IFERROR(INDEX(Aug!AK$6:AK$31,MATCH($A14,Aug!$A$6:$A$31,0)),0)+IFERROR(INDEX(Sep!AK$6:AK$31,MATCH($A14,Sep!$A$6:$A$31,0)),0)+IFERROR(INDEX(Oct!AK$6:AK$31,MATCH($A14,Oct!$A$6:$A$31,0)),0)+IFERROR(INDEX(Nov!AK$6:AK$31,MATCH($A14,Nov!$A$6:$A$31,0)),0)+IFERROR(INDEX(Dec!AK$6:AK$31,MATCH($A14,Dec!$A$6:$A$31,0)),0)+IFERROR(INDEX(Jan!AK$6:AK$32,MATCH($A14,Jan!$A$6:$A$32,0)),0)+IFERROR(INDEX(Feb!AK$6:AK$28,MATCH($A14,Feb!$A$6:$A$28,0)),0)+IFERROR(INDEX(Mar!AK$6:AK$31,MATCH($A14,Mar!$A$6:$A$31,0)),0)+IFERROR(INDEX(Apr!AK$6:AK$31,MATCH($A14,Apr!$A$6:$A$31,0)),0)+IFERROR(INDEX(May!AK$6:AK$31,MATCH($A14,May!$A$6:$A$31,0)),0)+IFERROR(INDEX(Jun!AK$6:AK$31,MATCH($A14,Jun!$A$6:$A$31,0)),0)+IFERROR(INDEX(Jul!AK$6:AK$31,MATCH($A14,Jul!$A$6:$A$31,0)),0) -> 0 | J14: =IF(I14>0, 5-I14, "") | K14: =IFERROR(INDEX(Aug!AL$6:AL$31,MATCH($A14,Aug!$A$6:$A$31,0)),0)+IFERROR(INDEX(Sep!AL$6:AL$31,MATCH($A14,Sep!$A$6:$A$31,0)),0)+IFERROR(INDEX(Oct!AL$6:AL$31,MATCH($A14,Oct!$A$6:$A$31,0)),0)+IFERROR(INDEX(Nov!AL$6:AL$31,MATCH($A14,Nov!$A$6:$A$31,0)),0)+IFERROR(INDEX(Dec!AL$6:AL$31,MATCH($A14,Dec!$A$6:$A$31,0)),0)+IFERROR(INDEX(Jan!AL$6:AL$32,MATCH($A14,Jan!$A$6:$A$32,0)),0)+IFERROR(INDEX(Feb!AL$6:AL$28,MATCH($A14,Feb!$A$6:$A$28,0)),0)+IFERROR(INDEX(Mar!AL$6:AL$31,MATCH($A14,Mar!$A$6:$A$31,0)),0)+IFERROR(INDEX(Apr!AL$6:AL$31,MATCH($A14,Apr!$A$6:$A$31,0)),0)+IFERROR(INDEX(May!AL$6:AL$31,MATCH($A14,May!$A$6:$A$31,0)),0)+IFERROR(INDEX(Jun!AL$6:AL$31,MATCH($A14,Jun!$A$6:$A$31,0)),0)+IFERROR(INDEX(Jul!AL$6:AL$31,MATCH($A14,Jul!$A$6:$A$31,0)),0) -> 0 | L14: =IF(K14>0, 5-K14, "") | M14: =IFERROR(INDEX(Aug!AM$6:AM$31,MATCH($A14,Aug!$A$6:$A$31,0)),0)+IFERROR(INDEX(Sep!AM$6:AM$31,MATCH($A14,Sep!$A$6:$A$31,0)),0)+IFERROR(INDEX(Oct!AM$6:AM$31,MATCH($A14,Oct!$A$6:$A$31,0)),0)+IFERROR(INDEX(Nov!AM$6:AM$31,MATCH($A14,Nov!$A$6:$A$31,0)),0)+IFERROR(INDEX(Dec!AM$6:AM$31,MATCH($A14,Dec!$A$6:$A$31,0)),0)+IFERROR(INDEX(Jan!AM$6:AM$32,MATCH($A14,Jan!$A$6:$A$32,0)),0)+IFERROR(INDEX(Feb!AM$6:AM$28,MATCH($A14,Feb!$A$6:$A$28,0)),0)+IFERROR(INDEX(Mar!AM$6:AM$31,MATCH($A14,Mar!$A$6:$A$31,0)),0)+IFERROR(INDEX(Apr!AM$6:AM$31,MATCH($A14,Apr!$A$6:$A$31,0)),0)+IFERROR(INDEX(May!AM$6:AM$31,MATCH($A14,May!$A$6:$A$31,0)),0)+IFERROR(INDEX(Jun!AM$6:AM$31,MATCH($A14,Jun!$A$6:$A$31,0)),0)+IFERROR(INDEX(Jul!AM$6:AM$31,MATCH($A14,Jul!$A$6:$A$31,0)),0) -> 0 | N14: =IF(M14>0, 5-M14, "") | O14: =IFERROR(INDEX(Aug!AN$6:AN$31,MATCH($A14,Aug!$A$6:$A$31,0)),0)+IFERROR(INDEX(Sep!AN$6:AN$31,MATCH($A14,Sep!$A$6:$A$31,0)),0)+IFERROR(INDEX(Oct!AN$6:AN$31,MATCH($A14,Oct!$A$6:$A$31,0)),0)+IFERROR(INDEX(Nov!AN$6:AN$31,MATCH($A14,Nov!$A$6:$A$31,0)),0)+IFERROR(INDEX(Dec!AN$6:AN$31,MATCH($A14,Dec!$A$6:$A$31,0)),0)+IFERROR(INDEX(Jan!AN$6:AN$32,MATCH($A14,Jan!$A$6:$A$32,0)),0)+IFERROR(INDEX(Feb!AN$6:AN$28,MATCH($A14,Feb!$A$6:$A$28,0)),0)+IFERROR(INDEX(Mar!AN$6:AN$31,MATCH($A14,Mar!$A$6:$A$31,0)),0)+IFERROR(INDEX(Apr!AN$6:AN$31,MATCH($A14,Apr!$A$6:$A$31,0)),0)+IFERROR(INDEX(May!AN$6:AN$31,MATCH($A14,May!$A$6:$A$31,0)),0)+IFERROR(INDEX(Jun!AN$6:AN$31,MATCH($A14,Jun!$A$6:$A$31,0)),0)+IFERROR(INDEX(Jul!AN$6:AN$31,MATCH($A14,Jul!$A$6:$A$31,0)),0) -> 0 | P14: =IF(O14>0, 5-O14, "") | Q14: =IFERROR(INDEX(Aug!AO$6:AO$31,MATCH($A14,Aug!$A$6:$A$31,0)),0)+IFERROR(INDEX(Sep!AO$6:AO$31,MATCH($A14,Sep!$A$6:$A$31,0)),0)+IFERROR(INDEX(Oct!AO$6:AO$31,MATCH($A14,Oct!$A$6:$A$31,0)),0)+IFERROR(INDEX(Nov!AO$6:AO$31,MATCH($A14,Nov!$A$6:$A$31,0)),0)+IFERROR(INDEX(Dec!AO$6:AO$31,MATCH($A14,Dec!$A$6:$A$31,0)),0)+IFERROR(INDEX(Jan!AO$6:AO$32,MATCH($A14,Jan!$A$6:$A$32,0)),0)+IFERROR(INDEX(Feb!AO$6:AO$28,MATCH($A14,Feb!$A$6:$A$28,0)),0)+IFERROR(INDEX(Mar!AO$6:AO$31,MATCH($A14,Mar!$A$6:$A$31,0)),0)+IFERROR(INDEX(Apr!AO$6:AO$31,MATCH($A14,Apr!$A$6:$A$31,0)),0)+IFERROR(INDEX(May!AO$6:AO$31,MATCH($A14,May!$A$6:$A$31,0)),0)+IFERROR(INDEX(Jun!AO$6:AO$31,MATCH($A14,Jun!$A$6:$A$31,0)),0)+IFERROR(INDEX(Jul!AO$6:AO$31,MATCH($A14,Jul!$A$6:$A$31,0)),0) -> 0 | R14: =IF(Q14>0, 7-Q14, "") | S14: =C14+E14+G14+I14+K14+M14+O14+Q14 -> 0
A15: 6 | B15: SHEHU NABILA | C15: =IFERROR(INDEX(Aug!AH$6:AH$31,MATCH($A15,Aug!$A$6:$A$31,0)),0)+IFERROR(INDEX(Sep!AH$6:AH$31,MATCH($A15,Sep!$A$6:$A$31,0)),0)+IFERROR(INDEX(Oct!AH$6:AH$31,MATCH($A15,Oct!$A$6:$A$31,0)),0)+IFERROR(INDEX(Nov!AH$6:AH$31,MATCH($A15,Nov!$A$6:$A$31,0)),0)+IFERROR(INDEX(Dec!AH$6:AH$31,MATCH($A15,Dec!$A$6:$A$31,0)),0)+IFERROR(INDEX(Jan!AH$6:AH$32,MATCH($A15,Jan!$A$6:$A$32,0)),0)+IFERROR(INDEX(Feb!AH$6:AH$28,MATCH($A15,Feb!$A$6:$A$28,0)),0)+IFERROR(INDEX(Mar!AH$6:AH$31,MATCH($A15,Mar!$A$6:$A$31,0)),0)+IFERROR(INDEX(Apr!AH$6:AH$31,MATCH($A15,Apr!$A$6:$A$31,0)),0)+IFERROR(INDEX(May!AH$6:AH$31,MATCH($A15,May!$A$6:$A$31,0)),0)+IFERROR(INDEX(Jun!AH$6:AH$31,MATCH($A15,Jun!$A$6:$A$31,0)),0)+IFERROR(INDEX(Jul!AH$6:AH$31,MATCH($A15,Jul!$A$6:$A$31,0)),0) -> 0 | D15: =IF(C15>0, 21-C15, "") | E15: =IFERROR(INDEX(Aug!AI$6:AI$31,MATCH($A15,Aug!$A$6:$A$31,0)),0)+IFERROR(INDEX(Sep!AI$6:AI$31,MATCH($A15,Sep!$A$6:$A$31,0)),0)+IFERROR(INDEX(Oct!AI$6:AI$31,MATCH($A15,Oct!$A$6:$A$31,0)),0)+IFERROR(INDEX(Nov!AI$6:AI$31,MATCH($A15,Nov!$A$6:$A$31,0)),0)+IFERROR(INDEX(Dec!AI$6:AI$31,MATCH($A15,Dec!$A$6:$A$31,0)),0)+IFERROR(INDEX(Jan!AI$6:AI$32,MATCH($A15,Jan!$A$6:$A$32,0)),0)+IFERROR(INDEX(Feb!AI$6:AI$28,MATCH($A15,Feb!$A$6:$A$28,0)),0)+IFERROR(INDEX(Mar!AI$6:AI$31,MATCH($A15,Mar!$A$6:$A$31,0)),0)+IFERROR(INDEX(Apr!AI$6:AI$31,MATCH($A15,Apr!$A$6:$A$31,0)),0)+IFERROR(INDEX(May!AI$6:AI$31,MATCH($A15,May!$A$6:$A$31,0)),0)+IFERROR(INDEX(Jun!AI$6:AI$31,MATCH($A15,Jun!$A$6:$A$31,0)),0)+IFERROR(INDEX(Jul!AI$6:AI$31,MATCH($A15,Jul!$A$6:$A$31,0)),0) -> 2 | F15: =IF(E15>0, 15-E15, "") -> 13 | G15: =IFERROR(INDEX(Aug!AJ$6:AJ$31,MATCH($A15,Aug!$A$6:$A$31,0)),0)+IFERROR(INDEX(Sep!AJ$6:AJ$31,MATCH($A15,Sep!$A$6:$A$31,0)),0)+IFERROR(INDEX(Oct!AJ$6:AJ$31,MATCH($A15,Oct!$A$6:$A$31,0)),0)+IFERROR(INDEX(Nov!AJ$6:AJ$31,MATCH($A15,Nov!$A$6:$A$31,0)),0)+IFERROR(INDEX(Dec!AJ$6:AJ$31,MATCH($A15,Dec!$A$6:$A$31,0)),0)+IFERROR(INDEX(Jan!AJ$6:AJ$32,MATCH($A15,Jan!$A$6:$A$32,0)),0)+IFERROR(INDEX(Feb!AJ$6:AJ$28,MATCH($A15,Feb!$A$6:$A$28,0)),0)+IFERROR(INDEX(Mar!AJ$6:AJ$31,MATCH($A15,Mar!$A$6:$A$31,0)),0)+IFERROR(INDEX(Apr!AJ$6:AJ$31,MATCH($A15,Apr!$A$6:$A$31,0)),0)+IFERROR(INDEX(May!AJ$6:AJ$31,MATCH($A15,May!$A$6:$A$31,0)),0)+IFERROR(INDEX(Jun!AJ$6:AJ$31,MATCH($A15,Jun!$A$6:$A$31,0)),0)+IFERROR(INDEX(Jul!AJ$6:AJ$31,MATCH($A15,Jul!$A$6:$A$31,0)),0) -> 0 | H15: =IF(G15>0, 80-G15, "") | I15: =IFERROR(INDEX(Aug!AK$6:AK$31,MATCH($A15,Aug!$A$6:$A$31,0)),0)+IFERROR(INDEX(Sep!AK$6:AK$31,MATCH($A15,Sep!$A$6:$A$31,0)),0)+IFERROR(INDEX(Oct!AK$6:AK$31,MATCH($A15,Oct!$A$6:$A$31,0)),0)+IFERROR(INDEX(Nov!AK$6:AK$31,MATCH($A15,Nov!$A$6:$A$31,0)),0)+IFERROR(INDEX(Dec!AK$6:AK$31,MATCH($A15,Dec!$A$6:$A$31,0)),0)+IFERROR(INDEX(Jan!AK$6:AK$32,MATCH($A15,Jan!$A$6:$A$32,0)),0)+IFERROR(INDEX(Feb!AK$6:AK$28,MATCH($A15,Feb!$A$6:$A$28,0)),0)+IFERROR(INDEX(Mar!AK$6:AK$31,MATCH($A15,Mar!$A$6:$A$31,0)),0)+IFERROR(INDEX(Apr!AK$6:AK$31,MATCH($A15,Apr!$A$6:$A$31,0)),0)+IFERROR(INDEX(May!AK$6:AK$31,MATCH($A15,May!$A$6:$A$31,0)),0)+IFERROR(INDEX(Jun!AK$6:AK$31,MATCH($A15,Jun!$A$6:$A$31,0)),0)+IFERROR(INDEX(Jul!AK$6:AK$31,MATCH($A15,Jul!$A$6:$A$31,0)),0) -> 0 | J15: =IF(I15>0, 5-I15, "") | K15: =IFERROR(INDEX(Aug!AL$6:AL$31,MATCH($A15,Aug!$A$6:$A$31,0)),0)+IFERROR(INDEX(Sep!AL$6:AL$31,MATCH($A15,Sep!$A$6:$A$31,0)),0)+IFERROR(INDEX(Oct!AL$6:AL$31,MATCH($A15,Oct!$A$6:$A$31,0)),0)+IFERROR(INDEX(Nov!AL$6:AL$31,MATCH($A15,Nov!$A$6:$A$31,0)),0)+IFERROR(INDEX(Dec!AL$6:AL$31,MATCH($A15,Dec!$A$6:$A$31,0)),0)+IFERROR(INDEX(Jan!AL$6:AL$32,MATCH($A15,Jan!$A$6:$A$32,0)),0)+IFERROR(INDEX(Feb!AL$6:AL$28,MATCH($A15,Feb!$A$6:$A$28,0)),0)+IFERROR(INDEX(Mar!AL$6:AL$31,MATCH($A15,Mar!$A$6:$A$31,0)),0)+IFERROR(INDEX(Apr!AL$6:AL$31,MATCH($A15,Apr!$A$6:$A$31,0)),0)+IFERROR(INDEX(May!AL$6:AL$31,MATCH($A15,May!$A$6:$A$31,0)),0)+IFERROR(INDEX(Jun!AL$6:AL$31,MATCH($A15,Jun!$A$6:$A$31,0)),0)+IFERROR(INDEX(Jul!AL$6:AL$31,MATCH($A15,Jul!$A$6:$A$31,0)),0) -> 0 | L15: =IF(K15>0, 5-K15, "") | M15: =IFERROR(INDEX(Aug!AM$6:AM$31,MATCH($A15,Aug!$A$6:$A$31,0)),0)+IFERROR(INDEX(Sep!AM$6:AM$31,MATCH($A15,Sep!$A$6:$A$31,0)),0)+IFERROR(INDEX(Oct!AM$6:AM$31,MATCH($A15,Oct!$A$6:$A$31,0)),0)+IFERROR(INDEX(Nov!AM$6:AM$31,MATCH($A15,Nov!$A$6:$A$31,0)),0)+IFERROR(INDEX(Dec!AM$6:AM$31,MATCH($A15,Dec!$A$6:$A$31,0)),0)+IFERROR(INDEX(Jan!AM$6:AM$32,MATCH($A15,Jan!$A$6:$A$32,0)),0)+IFERROR(INDEX(Feb!AM$6:AM$28,MATCH($A15,Feb!$A$6:$A$28,0)),0)+IFERROR(INDEX(Mar!AM$6:AM$31,MATCH($A15,Mar!$A$6:$A$31,0)),0)+IFERROR(INDEX(Apr!AM$6:AM$31,MATCH($A15,Apr!$A$6:$A$31,0)),0)+IFERROR(INDEX(May!AM$6:AM$31,MATCH($A15,May!$A$6:$A$31,0)),0)+IFERROR(INDEX(Jun!AM$6:AM$31,MATCH($A15,Jun!$A$6:$A$31,0)),0)+IFERROR(INDEX(Jul!AM$6:AM$31,MATCH($A15,Jul!$A$6:$A$31,0)),0) -> 0 | N15: =IF(M15>0, 5-M15, "") | O15: =IFERROR(INDEX(Aug!AN$6:AN$31,MATCH($A15,Aug!$A$6:$A$31,0)),0)+IFERROR(INDEX(Sep!AN$6:AN$31,MATCH($A15,Sep!$A$6:$A$31,0)),0)+IFERROR(INDEX(Oct!AN$6:AN$31,MATCH($A15,Oct!$A$6:$A$31,0)),0)+IFERROR(INDEX(Nov!AN$6:AN$31,MATCH($A15,Nov!$A$6:$A$31,0)),0)+IFERROR(INDEX(Dec!AN$6:AN$31,MATCH($A15,Dec!$A$6:$A$31,0)),0)+IFERROR(INDEX(Jan!AN$6:AN$32,MATCH($A15,Jan!$A$6:$A$32,0)),0)+IFERROR(INDEX(Feb!AN$6:AN$28,MATCH($A15,Feb!$A$6:$A$28,0)),0)+IFERROR(INDEX(Mar!AN$6:AN$31,MATCH($A15,Mar!$A$6:$A$31,0)),0)+IFERROR(INDEX(Apr!AN$6:AN$31,MATCH($A15,Apr!$A$6:$A$31,0)),0)+IFERROR(INDEX(May!AN$6:AN$31,MATCH($A15,May!$A$6:$A$31,0)),0)+IFERROR(INDEX(Jun!AN$6:AN$31,MATCH($A15,Jun!$A$6:$A$31,0)),0)+IFERROR(INDEX(Jul!AN$6:AN$31,MATCH($A15,Jul!$A$6:$A$31,0)),0) -> 0 | P15: =IF(O15>0, 5-O15, "") | Q15: =IFERROR(INDEX(Aug!AO$6:AO$31,MATCH($A15,Aug!$A$6:$A$31,0)),0)+IFERROR(INDEX(Sep!AO$6:AO$31,MATCH($A15,Sep!$A$6:$A$31,0)),0)+IFERROR(INDEX(Oct!AO$6:AO$31,MATCH($A15,Oct!$A$6:$A$31,0)),0)+IFERROR(INDEX(Nov!AO$6:AO$31,MATCH($A15,Nov!$A$6:$A$31,0)),0)+IFERROR(INDEX(Dec!AO$6:AO$31,MATCH($A15,Dec!$A$6:$A$31,0)),0)+IFERROR(INDEX(Jan!AO$6:AO$32,MATCH($A15,Jan!$A$6:$A$32,0)),0)+IFERROR(INDEX(Feb!AO$6:AO$28,MATCH($A15,Feb!$A$6:$A$28,0)),0)+IFERROR(INDEX(Mar!AO$6:AO$31,MATCH($A15,Mar!$A$6:$A$31,0)),0)+IFERROR(INDEX(Apr!AO$6:AO$31,MATCH($A15,Apr!$A$6:$A$31,0)),0)+IFERROR(INDEX(May!AO$6:AO$31,MATCH($A15,May!$A$6:$A$31,0)),0)+IFERROR(INDEX(Jun!AO$6:AO$31,MATCH($A15,Jun!$A$6:$A$31,0)),0)+IFERROR(INDEX(Jul!AO$6:AO$31,MATCH($A15,Jul!$A$6:$A$31,0)),0) -> 0 | R15: =IF(Q15>0, 7-Q15, "") | S15: =C15+E15+G15+I15+K15+M15+O15+Q15 -> 2
A16: 7 | B16: SULEMAN IBRAHIM | C16: =IFERROR(INDEX(Aug!AH$6:AH$31,MATCH($A16,Aug!$A$6:$A$31,0)),0)+IFERROR(INDEX(Sep!AH$6:AH$31,MATCH($A16,Sep!$A$6:$A$31,0)),0)+IFERROR(INDEX(Oct!AH$6:AH$31,MATCH($A16,Oct!$A$6:$A$31,0)),0)+IFERROR(INDEX(Nov!AH$6:AH$31,MATCH($A16,Nov!$A$6:$A$31,0)),0)+IFERROR(INDEX(Dec!AH$6:AH$31,MATCH($A16,Dec!$A$6:$A$31,0)),0)+IFERROR(INDEX(Jan!AH$6:AH$32,MATCH($A16,Jan!$A$6:$A$32,0)),0)+IFERROR(INDEX(Feb!AH$6:AH$28,MATCH($A16,Feb!$A$6:$A$28,0)),0)+IFERROR(INDEX(Mar!AH$6:AH$31,MATCH($A16,Mar!$A$6:$A$31,0)),0)+IFERROR(INDEX(Apr!AH$6:AH$31,MATCH($A16,Apr!$A$6:$A$31,0)),0)+IFERROR(INDEX(May!AH$6:AH$31,MATCH($A16,May!$A$6:$A$31,0)),0)+IFERROR(INDEX(Jun!AH$6:AH$31,MATCH($A16,Jun!$A$6:$A$31,0)),0)+IFERROR(INDEX(Jul!AH$6:AH$31,MATCH($A16,Jul!$A$6:$A$31,0)),0) -> 0 | D16: =IF(C16>0, 21-C16, "") | E16: =IFERROR(INDEX(Aug!AI$6:AI$31,MATCH($A16,Aug!$A$6:$A$31,0)),0)+IFERROR(INDEX(Sep!AI$6:AI$31,MATCH($A16,Sep!$A$6:$A$31,0)),0)+IFERROR(INDEX(Oct!AI$6:AI$31,MATCH($A16,Oct!$A$6:$A$31,0)),0)+IFERROR(INDEX(Nov!AI$6:AI$31,MATCH($A16,Nov!$A$6:$A$31,0)),0)+IFERROR(INDEX(Dec!AI$6:AI$31,MATCH($A16,Dec!$A$6:$A$31,0)),0)+IFERROR(INDEX(Jan!AI$6:AI$32,MATCH($A16,Jan!$A$6:$A$32,0)),0)+IFERROR(INDEX(Feb!AI$6:AI$28,MATCH($A16,Feb!$A$6:$A$28,0)),0)+IFERROR(INDEX(Mar!AI$6:AI$31,MATCH($A16,Mar!$A$6:$A$31,0)),0)+IFERROR(INDEX(Apr!AI$6:AI$31,MATCH($A16,Apr!$A$6:$A$31,0)),0)+IFERROR(INDEX(May!AI$6:AI$31,MATCH($A16,May!$A$6:$A$31,0)),0)+IFERROR(INDEX(Jun!AI$6:AI$31,MATCH($A16,Jun!$A$6:$A$31,0)),0)+IFERROR(INDEX(Jul!AI$6:AI$31,MATCH($A16,Jul!$A$6:$A$31,0)),0) -> 0 | F16: =IF(E16>0, 15-E16, "") | G16: =IFERROR(INDEX(Aug!AJ$6:AJ$31,MATCH($A16,Aug!$A$6:$A$31,0)),0)+IFERROR(INDEX(Sep!AJ$6:AJ$31,MATCH($A16,Sep!$A$6:$A$31,0)),0)+IFERROR(INDEX(Oct!AJ$6:AJ$31,MATCH($A16,Oct!$A$6:$A$31,0)),0)+IFERROR(INDEX(Nov!AJ$6:AJ$31,MATCH($A16,Nov!$A$6:$A$31,0)),0)+IFERROR(INDEX(Dec!AJ$6:AJ$31,MATCH($A16,Dec!$A$6:$A$31,0)),0)+IFERROR(INDEX(Jan!AJ$6:AJ$32,MATCH($A16,Jan!$A$6:$A$32,0)),0)+IFERROR(INDEX(Feb!AJ$6:AJ$28,MATCH($A16,Feb!$A$6:$A$28,0)),0)+IFERROR(INDEX(Mar!AJ$6:AJ$31,MATCH($A16,Mar!$A$6:$A$31,0)),0)+IFERROR(INDEX(Apr!AJ$6:AJ$31,MATCH($A16,Apr!$A$6:$A$31,0)),0)+IFERROR(INDEX(May!AJ$6:AJ$31,MATCH($A16,May!$A$6:$A$31,0)),0)+IFERROR(INDEX(Jun!AJ$6:AJ$31,MATCH($A16,Jun!$A$6:$A$31,0)),0)+IFERROR(INDEX(Jul!AJ$6:AJ$31,MATCH($A16,Jul!$A$6:$A$31,0)),0) -> 0 | H16: =IF(G16>0, 80-G16, "") | I16: =IFERROR(INDEX(Aug!AK$6:AK$31,MATCH($A16,Aug!$A$6:$A$31,0)),0)+IFERROR(INDEX(Sep!AK$6:AK$31,MATCH($A16,Sep!$A$6:$A$31,0)),0)+IFERROR(INDEX(Oct!AK$6:AK$31,MATCH($A16,Oct!$A$6:$A$31,0)),0)+IFERROR(INDEX(Nov!AK$6:AK$31,MATCH($A16,Nov!$A$6:$A$31,0)),0)+IFERROR(INDEX(Dec!AK$6:AK$31,MATCH($A16,Dec!$A$6:$A$31,0)),0)+IFERROR(INDEX(Jan!AK$6:AK$32,MATCH($A16,Jan!$A$6:$A$32,0)),0)+IFERROR(INDEX(Feb!AK$6:AK$28,MATCH($A16,Feb!$A$6:$A$28,0)),0)+IFERROR(INDEX(Mar!AK$6:AK$31,MATCH($A16,Mar!$A$6:$A$31,0)),0)+IFERROR(INDEX(Apr!AK$6:AK$31,MATCH($A16,Apr!$A$6:$A$31,0)),0)+IFERROR(INDEX(May!AK$6:AK$31,MATCH($A16,May!$A$6:$A$31,0)),0)+IFERROR(INDEX(Jun!AK$6:AK$31,MATCH($A16,Jun!$A$6:$A$31,0)),0)+IFERROR(INDEX(Jul!AK$6:AK$31,MATCH($A16,Jul!$A$6:$A$31,0)),0) -> 0 | J16: =IF(I16>0, 5-I16, "") | K16: =IFERROR(INDEX(Aug!AL$6:AL$31,MATCH($A16,Aug!$A$6:$A$31,0)),0)+IFERROR(INDEX(Sep!AL$6:AL$31,MATCH($A16,Sep!$A$6:$A$31,0)),0)+IFERROR(INDEX(Oct!AL$6:AL$31,MATCH($A16,Oct!$A$6:$A$31,0)),0)+IFERROR(INDEX(Nov!AL$6:AL$31,MATCH($A16,Nov!$A$6:$A$31,0)),0)+IFERROR(INDEX(Dec!AL$6:AL$31,MATCH($A16,Dec!$A$6:$A$31,0)),0)+IFERROR(INDEX(Jan!AL$6:AL$32,MATCH($A16,Jan!$A$6:$A$32,0)),0)+IFERROR(INDEX(Feb!AL$6:AL$28,MATCH($A16,Feb!$A$6:$A$28,0)),0)+IFERROR(INDEX(Mar!AL$6:AL$31,MATCH($A16,Mar!$A$6:$A$31,0)),0)+IFERROR(INDEX(Apr!AL$6:AL$31,MATCH($A16,Apr!$A$6:$A$31,0)),0)+IFERROR(INDEX(May!AL$6:AL$31,MATCH($A16,May!$A$6:$A$31,0)),0)+IFERROR(INDEX(Jun!AL$6:AL$31,MATCH($A16,Jun!$A$6:$A$31,0)),0)+IFERROR(INDEX(Jul!AL$6:AL$31,MATCH($A16,Jul!$A$6:$A$31,0)),0) -> 0 | L16: =IF(K16>0, 5-K16, "") | M16: =IFERROR(INDEX(Aug!AM$6:AM$31,MATCH($A16,Aug!$A$6:$A$31,0)),0)+IFERROR(INDEX(Sep!AM$6:AM$31,MATCH($A16,Sep!$A$6:$A$31,0)),0)+IFERROR(INDEX(Oct!AM$6:AM$31,MATCH($A16,Oct!$A$6:$A$31,0)),0)+IFERROR(INDEX(Nov!AM$6:AM$31,MATCH($A16,Nov!$A$6:$A$31,0)),0)+IFERROR(INDEX(Dec!AM$6:AM$31,MATCH($A16,Dec!$A$6:$A$31,0)),0)+IFERROR(INDEX(Jan!AM$6:AM$32,MATCH($A16,Jan!$A$6:$A$32,0)),0)+IFERROR(INDEX(Feb!AM$6:AM$28,MATCH($A16,Feb!$A$6:$A$28,0)),0)+IFERROR(INDEX(Mar!AM$6:AM$31,MATCH($A16,Mar!$A$6:$A$31,0)),0)+IFERROR(INDEX(Apr!AM$6:AM$31,MATCH($A16,Apr!$A$6:$A$31,0)),0)+IFERROR(INDEX(May!AM$6:AM$31,MATCH($A16,May!$A$6:$A$31,0)),0)+IFERROR(INDEX(Jun!AM$6:AM$31,MATCH($A16,Jun!$A$6:$A$31,0)),0)+IFERROR(INDEX(Jul!AM$6:AM$31,MATCH($A16,Jul!$A$6:$A$31,0)),0) -> 4 | N16: =IF(M16>0, 5-M16, "") -> 1 | O16: =IFERROR(INDEX(Aug!AN$6:AN$31,MATCH($A16,Aug!$A$6:$A$31,0)),0)+IFERROR(INDEX(Sep!AN$6:AN$31,MATCH($A16,Sep!$A$6:$A$31,0)),0)+IFERROR(INDEX(Oct!AN$6:AN$31,MATCH($A16,Oct!$A$6:$A$31,0)),0)+IFERROR(INDEX(Nov!AN$6:AN$31,MATCH($A16,Nov!$A$6:$A$31,0)),0)+IFERROR(INDEX(Dec!AN$6:AN$31,MATCH($A16,Dec!$A$6:$A$31,0)),0)+IFERROR(INDEX(Jan!AN$6:AN$32,MATCH($A16,Jan!$A$6:$A$32,0)),0)+IFERROR(INDEX(Feb!AN$6:AN$28,MATCH($A16,Feb!$A$6:$A$28,0)),0)+IFERROR(INDEX(Mar!AN$6:AN$31,MATCH($A16,Mar!$A$6:$A$31,0)),0)+IFERROR(INDEX(Apr!AN$6:AN$31,MATCH($A16,Apr!$A$6:$A$31,0)),0)+IFERROR(INDEX(May!AN$6:AN$31,MATCH($A16,May!$A$6:$A$31,0)),0)+IFERROR(INDEX(Jun!AN$6:AN$31,MATCH($A16,Jun!$A$6:$A$31,0)),0)+IFERROR(INDEX(Jul!AN$6:AN$31,MATCH($A16,Jul!$A$6:$A$31,0)),0) -> 0 | P16: =IF(O16>0, 5-O16, "") | Q16: =IFERROR(INDEX(Aug!AO$6:AO$31,MATCH($A16,Aug!$A$6:$A$31,0)),0)+IFERROR(INDEX(Sep!AO$6:AO$31,MATCH($A16,Sep!$A$6:$A$31,0)),0)+IFERROR(INDEX(Oct!AO$6:AO$31,MATCH($A16,Oct!$A$6:$A$31,0)),0)+IFERROR(INDEX(Nov!AO$6:AO$31,MATCH($A16,Nov!$A$6:$A$31,0)),0)+IFERROR(INDEX(Dec!AO$6:AO$31,MATCH($A16,Dec!$A$6:$A$31,0)),0)+IFERROR(INDEX(Jan!AO$6:AO$32,MATCH($A16,Jan!$A$6:$A$32,0)),0)+IFERROR(INDEX(Feb!AO$6:AO$28,MATCH($A16,Feb!$A$6:$A$28,0)),0)+IFERROR(INDEX(Mar!AO$6:AO$31,MATCH($A16,Mar!$A$6:$A$31,0)),0)+IFERROR(INDEX(Apr!AO$6:AO$31,MATCH($A16,Apr!$A$6:$A$31,0)),0)+IFERROR(INDEX(May!AO$6:AO$31,MATCH($A16,May!$A$6:$A$31,0)),0)+IFERROR(INDEX(Jun!AO$6:AO$31,MATCH($A16,Jun!$A$6:$A$31,0)),0)+IFERROR(INDEX(Jul!AO$6:AO$31,MATCH($A16,Jul!$A$6:$A$31,0)),0) -> 0 | R16: =IF(Q16>0, 7-Q16, "") | S16: =C16+E16+G16+I16+K16+M16+O16+Q16 -> 4 | T16: If you need to add more names, you will need to insert
A17: 8 | B17: EMMANUELA LONGJAP | C17: =IFERROR(INDEX(Aug!AH$6:AH$31,MATCH($A17,Aug!$A$6:$A$31,0)),0)+IFERROR(INDEX(Sep!AH$6:AH$31,MATCH($A17,Sep!$A$6:$A$31,0)),0)+IFERROR(INDEX(Oct!AH$6:AH$31,MATCH($A17,Oct!$A$6:$A$31,0)),0)+IFERROR(INDEX(Nov!AH$6:AH$31,MATCH($A17,Nov!$A$6:$A$31,0)),0)+IFERROR(INDEX(Dec!AH$6:AH$31,MATCH($A17,Dec!$A$6:$A$31,0)),0)+IFERROR(INDEX(Jan!AH$6:AH$32,MATCH($A17,Jan!$A$6:$A$32,0)),0)+IFERROR(INDEX(Feb!AH$6:AH$28,MATCH($A17,Feb!$A$6:$A$28,0)),0)+IFERROR(INDEX(Mar!AH$6:AH$31,MATCH($A17,Mar!$A$6:$A$31,0)),0)+IFERROR(INDEX(Apr!AH$6:AH$31,MATCH($A17,Apr!$A$6:$A$31,0)),0)+IFERROR(INDEX(May!AH$6:AH$31,MATCH($A17,May!$A$6:$A$31,0)),0)+IFERROR(INDEX(Jun!AH$6:AH$31,MATCH($A17,Jun!$A$6:$A$31,0)),0)+IFERROR(INDEX(Jul!AH$6:AH$31,MATCH($A17,Jul!$A$6:$A$31,0)),0) -> 0 | D17: =IF(C17>0, 21-C17, "") | E17: =IFERROR(INDEX(Aug!AI$6:AI$31,MATCH($A17,Aug!$A$6:$A$31,0)),0)+IFERROR(INDEX(Sep!AI$6:AI$31,MATCH($A17,Sep!$A$6:$A$31,0)),0)+IFERROR(INDEX(Oct!AI$6:AI$31,MATCH($A17,Oct!$A$6:$A$31,0)),0)+IFERROR(INDEX(Nov!AI$6:AI$31,MATCH($A17,Nov!$A$6:$A$31,0)),0)+IFERROR(INDEX(Dec!AI$6:AI$31,MATCH($A17,Dec!$A$6:$A$31,0)),0)+IFERROR(INDEX(Jan!AI$6:AI$32,MATCH($A17,Jan!$A$6:$A$32,0)),0)+IFERROR(INDEX(Feb!AI$6:AI$28,MATCH($A17,Feb!$A$6:$A$28,0)),0)+IFERROR(INDEX(Mar!AI$6:AI$31,MATCH($A17,Mar!$A$6:$A$31,0)),0)+IFERROR(INDEX(Apr!AI$6:AI$31,MATCH($A17,Apr!$A$6:$A$31,0)),0)+IFERROR(INDEX(May!AI$6:AI$31,MATCH($A17,May!$A$6:$A$31,0)),0)+IFERROR(INDEX(Jun!AI$6:AI$31,MATCH($A17,Jun!$A$6:$A$31,0)),0)+IFERROR(INDEX(Jul!AI$6:AI$31,MATCH($A17,Jul!$A$6:$A$31,0)),0) -> 0 | F17: =IF(E17>0, 15-E17, "") | G17: =IFERROR(INDEX(Aug!AJ$6:AJ$31,MATCH($A17,Aug!$A$6:$A$31,0)),0)+IFERROR(INDEX(Sep!AJ$6:AJ$31,MATCH($A17,Sep!$A$6:$A$31,0)),0)+IFERROR(INDEX(Oct!AJ$6:AJ$31,MATCH($A17,Oct!$A$6:$A$31,0)),0)+IFERROR(INDEX(Nov!AJ$6:AJ$31,MATCH($A17,Nov!$A$6:$A$31,0)),0)+IFERROR(INDEX(Dec!AJ$6:AJ$31,MATCH($A17,Dec!$A$6:$A$31,0)),0)+IFERROR(INDEX(Jan!AJ$6:AJ$32,MATCH($A17,Jan!$A$6:$A$32,0)),0)+IFERROR(INDEX(Feb!AJ$6:AJ$28,MATCH($A17,Feb!$A$6:$A$28,0)),0)+IFERROR(INDEX(Mar!AJ$6:AJ$31,MATCH($A17,Mar!$A$6:$A$31,0)),0)+IFERROR(INDEX(Apr!AJ$6:AJ$31,MATCH($A17,Apr!$A$6:$A$31,0)),0)+IFERROR(INDEX(May!AJ$6:AJ$31,MATCH($A17,May!$A$6:$A$31,0)),0)+IFERROR(INDEX(Jun!AJ$6:AJ$31,MATCH($A17,Jun!$A$6:$A$31,0)),0)+IFERROR(INDEX(Jul!AJ$6:AJ$31,MATCH($A17,Jul!$A$6:$A$31,0)),0) -> 0 | H17: =IF(G17>0, 80-G17, "") | I17: =IFERROR(INDEX(Aug!AK$6:AK$31,MATCH($A17,Aug!$A$6:$A$31,0)),0)+IFERROR(INDEX(Sep!AK$6:AK$31,MATCH($A17,Sep!$A$6:$A$31,0)),0)+IFERROR(INDEX(Oct!AK$6:AK$31,MATCH($A17,Oct!$A$6:$A$31,0)),0)+IFERROR(INDEX(Nov!AK$6:AK$31,MATCH($A17,Nov!$A$6:$A$31,0)),0)+IFERROR(INDEX(Dec!AK$6:AK$31,MATCH($A17,Dec!$A$6:$A$31,0)),0)+IFERROR(INDEX(Jan!AK$6:AK$32,MATCH($A17,Jan!$A$6:$A$32,0)),0)+IFERROR(INDEX(Feb!AK$6:AK$28,MATCH($A17,Feb!$A$6:$A$28,0)),0)+IFERROR(INDEX(Mar!AK$6:AK$31,MATCH($A17,Mar!$A$6:$A$31,0)),0)+IFERROR(INDEX(Apr!AK$6:AK$31,MATCH($A17,Apr!$A$6:$A$31,0)),0)+IFERROR(INDEX(May!AK$6:AK$31,MATCH($A17,May!$A$6:$A$31,0)),0)+IFERROR(INDEX(Jun!AK$6:AK$31,MATCH($A17,Jun!$A$6:$A$31,0)),0)+IFERROR(INDEX(Jul!AK$6:AK$31,MATCH($A17,Jul!$A$6:$A$31,0)),0) -> 0 | J17: =IF(I17>0, 5-I17, "") | K17: =IFERROR(INDEX(Aug!AL$6:AL$31,MATCH($A17,Aug!$A$6:$A$31,0)),0)+IFERROR(INDEX(Sep!AL$6:AL$31,MATCH($A17,Sep!$A$6:$A$31,0)),0)+IFERROR(INDEX(Oct!AL$6:AL$31,MATCH($A17,Oct!$A$6:$A$31,0)),0)+IFERROR(INDEX(Nov!AL$6:AL$31,MATCH($A17,Nov!$A$6:$A$31,0)),0)+IFERROR(INDEX(Dec!AL$6:AL$31,MATCH($A17,Dec!$A$6:$A$31,0)),0)+IFERROR(INDEX(Jan!AL$6:AL$32,MATCH($A17,Jan!$A$6:$A$32,0)),0)+IFERROR(INDEX(Feb!AL$6:AL$28,MATCH($A17,Feb!$A$6:$A$28,0)),0)+IFERROR(INDEX(Mar!AL$6:AL$31,MATCH($A17,Mar!$A$6:$A$31,0)),0)+IFERROR(INDEX(Apr!AL$6:AL$31,MATCH($A17,Apr!$A$6:$A$31,0)),0)+IFERROR(INDEX(May!AL$6:AL$31,MATCH($A17,May!$A$6:$A$31,0)),0)+IFERROR(INDEX(Jun!AL$6:AL$31,MATCH($A17,Jun!$A$6:$A$31,0)),0)+IFERROR(INDEX(Jul!AL$6:AL$31,MATCH($A17,Jul!$A$6:$A$31,0)),0) -> 0 | L17: =IF(K17>0, 5-K17, "") | M17: =IFERROR(INDEX(Aug!AM$6:AM$31,MATCH($A17,Aug!$A$6:$A$31,0)),0)+IFERROR(INDEX(Sep!AM$6:AM$31,MATCH($A17,Sep!$A$6:$A$31,0)),0)+IFERROR(INDEX(Oct!AM$6:AM$31,MATCH($A17,Oct!$A$6:$A$31,0)),0)+IFERROR(INDEX(Nov!AM$6:AM$31,MATCH($A17,Nov!$A$6:$A$31,0)),0)+IFERROR(INDEX(Dec!AM$6:AM$31,MATCH($A17,Dec!$A$6:$A$31,0)),0)+IFERROR(INDEX(Jan!AM$6:AM$32,MATCH($A17,Jan!$A$6:$A$32,0)),0)+IFERROR(INDEX(Feb!AM$6:AM$28,MATCH($A17,Feb!$A$6:$A$28,0)),0)+IFERROR(INDEX(Mar!AM$6:AM$31,MATCH($A17,Mar!$A$6:$A$31,0)),0)+IFERROR(INDEX(Apr!AM$6:AM$31,MATCH($A17,Apr!$A$6:$A$31,0)),0)+IFERROR(INDEX(May!AM$6:AM$31,MATCH($A17,May!$A$6:$A$31,0)),0)+IFERROR(INDEX(Jun!AM$6:AM$31,MATCH($A17,Jun!$A$6:$A$31,0)),0)+IFERROR(INDEX(Jul!AM$6:AM$31,MATCH($A17,Jul!$A$6:$A$31,0)),0) -> 0 | N17: =IF(M17>0, 5-M17, "") | O17: =IFERROR(INDEX(Aug!AN$6:AN$31,MATCH($A17,Aug!$A$6:$A$31,0)),0)+IFERROR(INDEX(Sep!AN$6:AN$31,MATCH($A17,Sep!$A$6:$A$31,0)),0)+IFERROR(INDEX(Oct!AN$6:AN$31,MATCH($A17,Oct!$A$6:$A$31,0)),0)+IFERROR(INDEX(Nov!AN$6:AN$31,MATCH($A17,Nov!$A$6:$A$31,0)),0)+IFERROR(INDEX(Dec!AN$6:AN$31,MATCH($A17,Dec!$A$6:$A$31,0)),0)+IFERROR(INDEX(Jan!AN$6:AN$32,MATCH($A17,Jan!$A$6:$A$32,0)),0)+IFERROR(INDEX(Feb!AN$6:AN$28,MATCH($A17,Feb!$A$6:$A$28,0)),0)+IFERROR(INDEX(Mar!AN$6:AN$31,MATCH($A17,Mar!$A$6:$A$31,0)),0)+IFERROR(INDEX(Apr!AN$6:AN$31,MATCH($A17,Apr!$A$6:$A$31,0)),0)+IFERROR(INDEX(May!AN$6:AN$31,MATCH($A17,May!$A$6:$A$31,0)),0)+IFERROR(INDEX(Jun!AN$6:AN$31,MATCH($A17,Jun!$A$6:$A$31,0)),0)+IFERROR(INDEX(Jul!AN$6:AN$31,MATCH($A17,Jul!$A$6:$A$31,0)),0) -> 0 | P17: =IF(O17>0, 5-O17, "") | Q17: =IFERROR(INDEX(Aug!AO$6:AO$31,MATCH($A17,Aug!$A$6:$A$31,0)),0)+IFERROR(INDEX(Sep!AO$6:AO$31,MATCH($A17,Sep!$A$6:$A$31,0)),0)+IFERROR(INDEX(Oct!AO$6:AO$31,MATCH($A17,Oct!$A$6:$A$31,0)),0)+IFERROR(INDEX(Nov!AO$6:AO$31,MATCH($A17,Nov!$A$6:$A$31,0)),0)+IFERROR(INDEX(Dec!AO$6:AO$31,MATCH($A17,Dec!$A$6:$A$31,0)),0)+IFERROR(INDEX(Jan!AO$6:AO$32,MATCH($A17,Jan!$A$6:$A$32,0)),0)+IFERROR(INDEX(Feb!AO$6:AO$28,MATCH($A17,Feb!$A$6:$A$28,0)),0)+IFERROR(INDEX(Mar!AO$6:AO$31,MATCH($A17,Mar!$A$6:$A$31,0)),0)+IFERROR(INDEX(Apr!AO$6:AO$31,MATCH($A17,Apr!$A$6:$A$31,0)),0)+IFERROR(INDEX(May!AO$6:AO$31,MATCH($A17,May!$A$6:$A$31,0)),0)+IFERROR(INDEX(Jun!AO$6:AO$31,MATCH($A17,Jun!$A$6:$A$31,0)),0)+IFERROR(INDEX(Jul!AO$6:AO$31,MATCH($A17,Jul!$A$6:$A$31,0)),0) -> 0 | R17: =IF(Q17>0, 7-Q17, "") | S17: =C17+E17+G17+I17+K17+M17+O17+Q17 -> 0 | T17: new rows ABOVE the last row in the tables (the gray row).
A18: 9 | B18: OLUCHI EZE | C18: =IFERROR(INDEX(Aug!AH$6:AH$31,MATCH($A18,Aug!$A$6:$A$31,0)),0)+IFERROR(INDEX(Sep!AH$6:AH$31,MATCH($A18,Sep!$A$6:$A$31,0)),0)+IFERROR(INDEX(Oct!AH$6:AH$31,MATCH($A18,Oct!$A$6:$A$31,0)),0)+IFERROR(INDEX(Nov!AH$6:AH$31,MATCH($A18,Nov!$A$6:$A$31,0)),0)+IFERROR(INDEX(Dec!AH$6:AH$31,MATCH($A18,Dec!$A$6:$A$31,0)),0)+IFERROR(INDEX(Jan!AH$6:AH$32,MATCH($A18,Jan!$A$6:$A$32,0)),0)+IFERROR(INDEX(Feb!AH$6:AH$28,MATCH($A18,Feb!$A$6:$A$28,0)),0)+IFERROR(INDEX(Mar!AH$6:AH$31,MATCH($A18,Mar!$A$6:$A$31,0)),0)+IFERROR(INDEX(Apr!AH$6:AH$31,MATCH($A18,Apr!$A$6:$A$31,0)),0)+IFERROR(INDEX(May!AH$6:AH$31,MATCH($A18,May!$A$6:$A$31,0)),0)+IFERROR(INDEX(Jun!AH$6:AH$31,MATCH($A18,Jun!$A$6:$A$31,0)),0)+IFERROR(INDEX(Jul!AH$6:AH$31,MATCH($A18,Jul!$A$6:$A$31,0)),0) -> 0 | D18: =IF(C18>0, 21-C18, "") | E18: =IFERROR(INDEX(Aug!AI$6:AI$31,MATCH($A18,Aug!$A$6:$A$31,0)),0)+IFERROR(INDEX(Sep!AI$6:AI$31,MATCH($A18,Sep!$A$6:$A$31,0)),0)+IFERROR(INDEX(Oct!AI$6:AI$31,MATCH($A18,Oct!$A$6:$A$31,0)),0)+IFERROR(INDEX(Nov!AI$6:AI$31,MATCH($A18,Nov!$A$6:$A$31,0)),0)+IFERROR(INDEX(Dec!AI$6:AI$31,MATCH($A18,Dec!$A$6:$A$31,0)),0)+IFERROR(INDEX(Jan!AI$6:AI$32,MATCH($A18,Jan!$A$6:$A$32,0)),0)+IFERROR(INDEX(Feb!AI$6:AI$28,MATCH($A18,Feb!$A$6:$A$28,0)),0)+IFERROR(INDEX(Mar!AI$6:AI$31,MATCH($A18,Mar!$A$6:$A$31,0)),0)+IFERROR(INDEX(Apr!AI$6:AI$31,MATCH($A18,Apr!$A$6:$A$31,0)),0)+IFERROR(INDEX(May!AI$6:AI$31,MATCH($A18,May!$A$6:$A$31,0)),0)+IFERROR(INDEX(Jun!AI$6:AI$31,MATCH($A18,Jun!$A$6:$A$31,0)),0)+IFERROR(INDEX(Jul!AI$6:AI$31,MATCH($A18,Jul!$A$6:$A$31,0)),0) -> 0 | F18: =IF(E18>0, 15-E18, "") | G18: =IFERROR(INDEX(Aug!AJ$6:AJ$31,MATCH($A18,Aug!$A$6:$A$31,0)),0)+IFERROR(INDEX(Sep!AJ$6:AJ$31,MATCH($A18,Sep!$A$6:$A$31,0)),0)+IFERROR(INDEX(Oct!AJ$6:AJ$31,MATCH($A18,Oct!$A$6:$A$31,0)),0)+IFERROR(INDEX(Nov!AJ$6:AJ$31,MATCH($A18,Nov!$A$6:$A$31,0)),0)+IFERROR(INDEX(Dec!AJ$6:AJ$31,MATCH($A18,Dec!$A$6:$A$31,0)),0)+IFERROR(INDEX(Jan!AJ$6:AJ$32,MATCH($A18,Jan!$A$6:$A$32,0)),0)+IFERROR(INDEX(Feb!AJ$6:AJ$28,MATCH($A18,Feb!$A$6:$A$28,0)),0)+IFERROR(INDEX(Mar!AJ$6:AJ$31,MATCH($A18,Mar!$A$6:$A$31,0)),0)+IFERROR(INDEX(Apr!AJ$6:AJ$31,MATCH($A18,Apr!$A$6:$A$31,0)),0)+IFERROR(INDEX(May!AJ$6:AJ$31,MATCH($A18,May!$A$6:$A$31,0)),0)+IFERROR(INDEX(Jun!AJ$6:AJ$31,MATCH($A18,Jun!$A$6:$A$31,0)),0)+IFERROR(INDEX(Jul!AJ$6:AJ$31,MATCH($A18,Jul!$A$6:$A$31,0)),0) -> 0 | H18: =IF(G18>0, 80-G18, "") | I18: =IFERROR(INDEX(Aug!AK$6:AK$31,MATCH($A18,Aug!$A$6:$A$31,0)),0)+IFERROR(INDEX(Sep!AK$6:AK$31,MATCH($A18,Sep!$A$6:$A$31,0)),0)+IFERROR(INDEX(Oct!AK$6:AK$31,MATCH($A18,Oct!$A$6:$A$31,0)),0)+IFERROR(INDEX(Nov!AK$6:AK$31,MATCH($A18,Nov!$A$6:$A$31,0)),0)+IFERROR(INDEX(Dec!AK$6:AK$31,MATCH($A18,Dec!$A$6:$A$31,0)),0)+IFERROR(INDEX(Jan!AK$6:AK$32,MATCH($A18,Jan!$A$6:$A$32,0)),0)+IFERROR(INDEX(Feb!AK$6:AK$28,MATCH($A18,Feb!$A$6:$A$28,0)),0)+IFERROR(INDEX(Mar!AK$6:AK$31,MATCH($A18,Mar!$A$6:$A$31,0)),0)+IFERROR(INDEX(Apr!AK$6:AK$31,MATCH($A18,Apr!$A$6:$A$31,0)),0)+IFERROR(INDEX(May!AK$6:AK$31,MATCH($A18,May!$A$6:$A$31,0)),0)+IFERROR(INDEX(Jun!AK$6:AK$31,MATCH($A18,Jun!$A$6:$A$31,0)),0)+IFERROR(INDEX(Jul!AK$6:AK$31,MATCH($A18,Jul!$A$6:$A$31,0)),0) -> 0 | J18: =IF(I18>0, 5-I18, "") | K18: =IFERROR(INDEX(Aug!AL$6:AL$31,MATCH($A18,Aug!$A$6:$A$31,0)),0)+IFERROR(INDEX(Sep!AL$6:AL$31,MATCH($A18,Sep!$A$6:$A$31,0)),0)+IFERROR(INDEX(Oct!AL$6:AL$31,MATCH($A18,Oct!$A$6:$A$31,0)),0)+IFERROR(INDEX(Nov!AL$6:AL$31,MATCH($A18,Nov!$A$6:$A$31,0)),0)+IFERROR(INDEX(Dec!AL$6:AL$31,MATCH($A18,Dec!$A$6:$A$31,0)),0)+IFERROR(INDEX(Jan!AL$6:AL$32,MATCH($A18,Jan!$A$6:$A$32,0)),0)+IFERROR(INDEX(Feb!AL$6:AL$28,MATCH($A18,Feb!$A$6:$A$28,0)),0)+IFERROR(INDEX(Mar!AL$6:AL$31,MATCH($A18,Mar!$A$6:$A$31,0)),0)+IFERROR(INDEX(Apr!AL$6:AL$31,MATCH($A18,Apr!$A$6:$A$31,0)),0)+IFERROR(INDEX(May!AL$6:AL$31,MATCH($A18,May!$A$6:$A$31,0)),0)+IFERROR(INDEX(Jun!AL$6:AL$31,MATCH($A18,Jun!$A$6:$A$31,0)),0)+IFERROR(INDEX(Jul!AL$6:AL$31,MATCH($A18,Jul!$A$6:$A$31,0)),0) -> 0 | L18: =IF(K18>0, 5-K18, "") | M18: =IFERROR(INDEX(Aug!AM$6:AM$31,MATCH($A18,Aug!$A$6:$A$31,0)),0)+IFERROR(INDEX(Sep!AM$6:AM$31,MATCH($A18,Sep!$A$6:$A$31,0)),0)+IFERROR(INDEX(Oct!AM$6:AM$31,MATCH($A18,Oct!$A$6:$A$31,0)),0)+IFERROR(INDEX(Nov!AM$6:AM$31,MATCH($A18,Nov!$A$6:$A$31,0)),0)+IFERROR(INDEX(Dec!AM$6:AM$31,MATCH($A18,Dec!$A$6:$A$31,0)),0)+IFERROR(INDEX(Jan!AM$6:AM$32,MATCH($A18,Jan!$A$6:$A$32,0)),0)+IFERROR(INDEX(Feb!AM$6:AM$28,MATCH($A18,Feb!$A$6:$A$28,0)),0)+IFERROR(INDEX(Mar!AM$6:AM$31,MATCH($A18,Mar!$A$6:$A$31,0)),0)+IFERROR(INDEX(Apr!AM$6:AM$31,MATCH($A18,Apr!$A$6:$A$31,0)),0)+IFERROR(INDEX(May!AM$6:AM$31,MATCH($A18,May!$A$6:$A$31,0)),0)+IFERROR(INDEX(Jun!AM$6:AM$31,MATCH($A18,Jun!$A$6:$A$31,0)),0)+IFERROR(INDEX(Jul!AM$6:AM$31,MATCH($A18,Jul!$A$6:$A$31,0)),0) -> 0 | N18: =IF(M18>0, 5-M18, "") | O18: =IFERROR(INDEX(Aug!AN$6:AN$31,MATCH($A18,Aug!$A$6:$A$31,0)),0)+IFERROR(INDEX(Sep!AN$6:AN$31,MATCH($A18,Sep!$A$6:$A$31,0)),0)+IFERROR(INDEX(Oct!AN$6:AN$31,MATCH($A18,Oct!$A$6:$A$31,0)),0)+IFERROR(INDEX(Nov!AN$6:AN$31,MATCH($A18,Nov!$A$6:$A$31,0)),0)+IFERROR(INDEX(Dec!AN$6:AN$31,MATCH($A18,Dec!$A$6:$A$31,0)),0)+IFERROR(INDEX(Jan!AN$6:AN$32,MATCH($A18,Jan!$A$6:$A$32,0)),0)+IFERROR(INDEX(Feb!AN$6:AN$28,MATCH($A18,Feb!$A$6:$A$28,0)),0)+IFERROR(INDEX(Mar!AN$6:AN$31,MATCH($A18,Mar!$A$6:$A$31,0)),0)+IFERROR(INDEX(Apr!AN$6:AN$31,MATCH($A18,Apr!$A$6:$A$31,0)),0)+IFERROR(INDEX(May!AN$6:AN$31,MATCH($A18,May!$A$6:$A$31,0)),0)+IFERROR(INDEX(Jun!AN$6:AN$31,MATCH($A18,Jun!$A$6:$A$31,0)),0)+IFERROR(INDEX(Jul!AN$6:AN$31,MATCH($A18,Jul!$A$6:$A$31,0)),0) -> 0 | P18: =IF(O18>0, 5-O18, "") | Q18: =IFERROR(INDEX(Aug!AO$6:AO$31,MATCH($A18,Aug!$A$6:$A$31,0)),0)+IFERROR(INDEX(Sep!AO$6:AO$31,MATCH($A18,Sep!$A$6:$A$31,0)),0)+IFERROR(INDEX(Oct!AO$6:AO$31,MATCH($A18,Oct!$A$6:$A$31,0)),0)+IFERROR(INDEX(Nov!AO$6:AO$31,MATCH($A18,Nov!$A$6:$A$31,0)),0)+IFERROR(INDEX(Dec!AO$6:AO$31,MATCH($A18,Dec!$A$6:$A$31,0)),0)+IFERROR(INDEX(Jan!AO$6:AO$32,MATCH($A18,Jan!$A$6:$A$32,0)),0)+IFERROR(INDEX(Feb!AO$6:AO$28,MATCH($A18,Feb!$A$6:$A$28,0)),0)+IFERROR(INDEX(Mar!AO$6:AO$31,MATCH($A18,Mar!$A$6:$A$31,0)),0)+IFERROR(INDEX(Apr!AO$6:AO$31,MATCH($A18,Apr!$A$6:$A$31,0)),0)+IFERROR(INDEX(May!AO$6:AO$31,MATCH($A18,May!$A$6:$A$31,0)),0)+IFERROR(INDEX(Jun!AO$6:AO$31,MATCH($A18,Jun!$A$6:$A$31,0)),0)+IFERROR(INDEX(Jul!AO$6:AO$31,MATCH($A18,Jul!$A$6:$A$31,0)),0) -> 0 | R18: =IF(Q18>0, 7-Q18, "") | S18: =C18+E18+G18+I18+K18+M18+O18+Q18 -> 0
